Workbook
Name Actual_Ratio: REPORT!$N$7
Name Actual_TDY: 'DATA INPUT'!$E$141:$E$156
Name Actual_YSD: 'DATA INPUT'!$F$141:$F$156
Name AGActual_Ratio: REPORT!$H$5
Name API_RANGE: TEMPERATURE!$C$2:$BA$2
Name AUTOFILL01: 'WELL DATA'!$CV$4:$DP$190
Name AUTOFILL02: 'WATER FLOOD WELLS'!$AW$3:$BF$44
Name AUTOFILL03: 'WELL TESTS'!$AR$3:$BK$14
Name AUTOFILL04: 'WELL TESTS'!$L$3:$L$14
Name AUTOFILL05: 'WELL TESTS'!$O$3:$O$14
Name AUTOFILL06: 'LAB DATA'!#REF!
Name AUTOFILL06: 'DFL SHOTS'!$Z$3:$AJ$20
Name AUTOFILL07: 'LAB DATA'!$I$3:$I$23
Name AUTOFILL07: 'DFL SHOTS'!$J$3:$J$20
Name AUTOFILL08: 'WELL DATA'!$F$4:$F$190
Name AUTOFILL09: 'WELL DATA'!$AM$4:$AM$190
Name AUTOFILL10: 'WATER FLOOD WELLS'!$N$5:$N$11
Name AUTOFILL11: 'WELL DATA'!$AG$4:$AG$190
Name AUTOFILL13: 'EQUIPMENT DATA'!$AJ$3:$AT$26
Name AUTOFILL14: MANIFOLDS!$AJ$3:$AP$28
Name BFPD: 'WELL DATA'!$AI$4:$AI$190
Name BOPD: 'WELL DATA'!$AM:$AM
Name BSSTATUS: TANKS!$C$3:$C$6
Name BSW: 'WELL DATA'!$AJ$4:$AJ$190
Name CALC01: 'WELL DATA'!$CV$4:$DP$4
Name CALC02: 'WATER FLOOD WELLS'!$AW$3:$BF$3
Name CALC03: 'WELL TESTS'!$AR$4:$BK$4
Name CALC04: 'WELL TESTS'!$L$3
Name CALC05: 'WELL TESTS'!$O$3
Name CALC06: 'LAB DATA'!#REF!
Name CALC06: 'DFL SHOTS'!$Z$3:$AJ$3
Name CALC07: 'LAB DATA'!$I$3
Name CALC07: 'DFL SHOTS'!$J$3
Name CALC08: 'WELL DATA'!$F$4
Name CALC09: 'WELL DATA'!$AM$4
Name CALC10: 'WATER FLOOD WELLS'!$N$5
Name CALC11: 'WELL DATA'!$AG$4
Name CALC13: 'EQUIPMENT DATA'!$AJ$3:$AT$3
Name CALC14: MANIFOLDS!$AJ$3:$AP$3
Name CASING_STATUS: ADMIN!$P$39:$P$40
Name CHOKE: ADMIN!$P$3:$P$35
Name CLEARPF: REPORT!#REF!
Name CLEARRANGE01: REPORT!$B$65:$O$73,REPORT!$B$75:$N$83,REPORT!$B$87:$O$110
Name CLEARRANGE02: 'WELL TESTS'!$B$4:$K$8,'WELL TESTS'!$M$4:$N$8,'WELL TESTS'!$P$4:$Y$8
Name CLEARRANGE03: 'WELL DATA'!$AN$5:$AO$190
Name CLEARRANGE05: 'LAB DATA'!$B$4:$J$23
Name CLEARRANGE05: 'DFL SHOTS'!$B$4:$M$20
Name CLEARRANGE06: 'EQUIPMENT DATA'!$D$3:$I$26
Name CLEARRANGE07: 'DATA INPUT'!$G$35:$I$132
Name CLEARRANGE08: 'DATA INPUT'!$E$3:$E$30
Name CLEARRANGE09: 'EQUIPMENT DATA'!$D$4:$I$26
Name CLOSINGSTK: REPORT!$D$38:$F$38
Name COMMENT: REPORT!$B$56:$L$106
Name COPYTARG02: #REF!
Name COPYTARG02: #REF!
Name CPF_LIST: ADMIN!#REF!
Name CPF_LIST: ADMIN!#REF!
Name DATATAG: 'WELL TESTS'!$AR$4:$AR$14
Name DEF_PROD: 'WELL DATA'!$F:$F
Name DELTA_DAY: 'DATA INPUT'!$S$2

Sheet REPORT
A1: rep | AU1: AVOCET TAG | AV1: DATE | AW1: PLANT | AX1: TYPE | AY1: METER NAME | AZ1: MT | BA1: LIQUID | BB1: GAS | BC1: COMMENTS
AU2: KHALDA_METER | AV2: =REPORTDATE-1 -> 46298 | AW2: 9AG OIL PLANT | AX2: B | AY2: AG OIL | AZ2: L | BA2: =N8-'DATA INPUT'!E7 -> 10855.889 | BC2: ADD Meter:ALLOCATED ON OIL WELLS W/O SAG SEP WELLS and WD-33-15
B3: ="VERSION "&VERSION -> VERSION 1.6 | D3: KHALDA PETROLEUM COMPANY | K3: =+REPDATE -> 46299 | AU3: KHALDA_METER | AV3: =REPORTDATE-1 -> 46298 | AW3: 9AG OIL PLANT | AX3: B | AY3: AG COND | AZ3: L | BA3: =N9 -> 665.39671 | BC3: Reference Meter:COND PRODUCTION | CD3: Click this button to save the file to the X: drive (as FILE1,xls)
D4: Production Day Ending @ 0600 Hours | AU4: KHALDA_METER | AV4: =REPORTDATE-1 -> 46298 | AW4: 9AG OIL PLANT | AX4: B | AY4: GPC | AZ4: L | BA4: =N38 -> 123.04943 | BC4: Reference Meter
B5: ABU ELGHARADIG (AG) OIL PLANT | E5: PRODUCTION SUMMARY | H5: =(N8+N10-H27)/(L8+L10-E27) -> 1.0004025 | L5: Production BBLs | M5: TDY V YST | N5: Actual BBL | O5: TDY V YST | AU5: KHALDA_METER | AV5: =REPORTDATE-1 -> 46298 | AW5: 9AG OIL PLANT | AX5: B | AY5: PRODUCTION FLARE GAS | AZ5: O | BB5: ='DATA INPUT'!E5 -> 665.129 | BC5: Reference Meter: FLARE GAS BETWEEN OIL PLANT AND GAS PLANT
B6: FIELD NAME | C6: FLOWING WELLS | D6: GAS PROD MMSCFD | E6: NET PROD TODAY | F6: NET PROD YESTERDAY | G6: DELTA | H6: ACTUAL | J6: EA TOTAL OIL PRODUCTION | L6: =L13+L20 -> 24206.345 | M6: =L6-'DATA INPUT'!F30 -> 26.344747 | N6: =N13+N20 -> 24215.01 | O6: ='DATA INPUT'!E141-'DATA INPUT'!F141 -> 9.1405579 | AU6: KHALDA_METER | AV6: =REPORTDATE-1 -> 46298 | AW6: 9AG OIL PLANT | AX6: B | AY6: WD TOTAL OIL PRODUCTION | AZ6: L | BA6: =N6 -> 24215.01 | BC6: Reference Meter: AG TOTAL OIL + COND + RZK PROD + NRQ PROD
B7: AG | C7: =IFERROR(IF(TDYPROD=0,0,COUNTIF(FIELD,"AG")),"") -> 20 | D7: =IFERROR(SUMIF(FIELD,"AG",EST_GASPROD)*GAS_PROFAC,"")+IFERROR(SUMIF(FIELD,"AG",GASLIFT)*GAS_PROFAC,"") -> 12.175814 | E7: =IFERROR(SUMIF(FIELD,"AG",EST_PROD)*OIL_PROFAC,"") -> 1128.5928 | F7: 1153.856 | G7: =IF(E7="","",E7-F7) -> -25.263218 | H7: =AGActual_Ratio*E7 -> 1129.047 | N7: =(BB21-AZ25-AZ30)/(AW21-AX25-AX30) -> 1.0004025 | AU7: KHALDA_METER | AV7: =REPORTDATE-1 -> 46298 | AW7: 9AG OIL PLANT | AX7: B | AY7: AG TOTAL OIL PRODUCTION | AZ7: L | BA7: =N8+N10 -> 11110.992 | BC7: Reference Meter: AG PROD FROM TANKS (all wells including SAG SEP wells) - AG Cond - OAPCO ( bec. it is coming on the same tanks
B8: BOLTNAIL | C8: =IFERROR(IF(TDYPROD=0,0,COUNTIF(FIELD,"BOLTNAIL")),"")+IFERROR(IF(TDYPROD=0,0,COUNTIF(FIELD,"BOLT")),"") -> 1 | D8: =IFERROR(SUMIF(FIELD,"BOLTNAIL",EST_GASPROD)*GAS_PROFAC,"")+IFERROR(SUMIF(FIELD,"BOLTNAIL",GASLIFT)*GAS_PROFAC,"") -> 0 | E8: =IFERROR(SUMIF(FIELD,"BOLTNAIL",EST_PROD),"")+L37 -> 47 | F8: 43 | G8: =IF(E8="","",E8-F8) -> 4 | H8: =AGActual_Ratio*E8 -> 47.018917 | J8: AG NET OIL PRODUCTION | L8: =H39-L9-'DATA INPUT'!E21-'DATA INPUT'!E24 -> 10851.522 | M8: =L8-'DATA INPUT'!F29 -> -200.47825 | N8: =L8*Actual_Ratio -> 10855.889 | O8: ='DATA INPUT'!E143-'DATA INPUT'!F143 -> -210.76499 | AU8: KHALDA_METER | AV8: =REPORTDATE-1 -> 46298 | AW8: 9AG OIL PLANT | AX8: B | AY8: AG INJ | AZ8: L | BA8: =SUM('WATER FLOOD WELLS'!H3:H44) -> 31095
B9: SAG | C9: =IFERROR(IF(TDYPROD=0,0,COUNTIF(FIELD,"SAG")),"") -> 8 | D9: =IFERROR(SUMIF(FIELD,"SAG",EST_GASPROD)*GAS_PROFAC,"")+IFERROR(SUMIF(FIELD,"SAG",GASLIFT)*GAS_PROFAC,"") -> 8.3706364 | E9: =IFERROR(SUMIF(FIELD,"SAG",EST_PROD)*OIL_PROFAC,"") -> 1239.9556 | F9: 1257.4748 | G9: =IF(E9="","",E9-F9) -> -17.519128 | H9: =AGActual_Ratio*E9 -> 1240.4547 | J9: AG CONDENSATE | L9: ='DATA INPUT'!E5 -> 665.129 | M9: =REPORT!L9-'DATA INPUT'!F5 -> 5.398 | N9: =L9*Actual_Ratio -> 665.39671 | O9: ='DATA INPUT'!E144-'DATA INPUT'!F144 -> 4.8141881 | AU9: KHALDA_METER | AV9: =REPORTDATE-1 -> 46298 | AW9: 9WD-33 | AX9: B | AY9: WD-33 OIL | AZ9: L | BA9: =N10 -> 255.10264 | BC9: Reference Meter: Used for injection in AG
B10: SWAG | C10: =IFERROR(IF(TDYPROD=0,0,COUNTIF(FIELD,"SWAG")),"") -> 3 | D10: =IFERROR(SUMIF(FIELD,"SWAG",EST_GASPROD)*GAS_PROFAC,"")+IFERROR(SUMIF(FIELD,"SWAG",GASLIFT)*GAS_PROFAC,"") -> 3.8456361 | E10: =IFERROR(SUMIF(FIELD,"SWAG",EST_PROD)*OIL_PROFAC,"") -> 77.44775 | F10: 79.190059 | G10: =IF(E10="","",E10-F10) -> -1.742309 | H10: =AGActual_Ratio*E10 -> 77.478923 | J10: WD-33 OIL PRODUCTION | L10: ='DATA INPUT'!E26 -> 255 | M10: =L10-'DATA INPUT'!F26 -> 2 | N10: =L10*Actual_Ratio -> 255.10264 | O10: ='DATA INPUT'!E145-'DATA INPUT'!F145 -> 1.776086 | AU10: KHALDA_METER | AV10: =REPORTDATE-1 -> 46298 | AW10: 9WD-33-15 | AX10: B | AY10: WD-33-15 OIL | AZ10: L | BA10: =N11 -> 5915.38 | BC10: ADD Meter: WD-33-15 Oil for production
B11: OAKHILL-W | C11: =IFERROR(IF(TDYPROD=0,0,COUNTIF(FIELD,"OAKHILL-W")),"")+IFERROR(IF(TDYPROD=0,0,COUNTIF(FIELD,"OAKHILL-SW")),"") -> 2 | D11: =IFERROR(SUMIF(FIELD,"OAKHILL-W",EST_GASPROD)*GAS_PROFAC,"")+IFERROR(SUMIF(FIELD,"OAKHILL-W",GASLIFT)*GAS_PROFAC,"") -> 0 | E11: =IFERROR(SUMIF(FIELD,"OAKHILL-W",EST_PROD)*OIL_PROFAC,"")+IFERROR(SUMIF(FIELD,"OAKHILL-SW",EST_PROD)*OIL_PROFAC,"") -> 526.57435 | F11: 538.42047 | G11: =IF(E11="","",E11-F11) -> -11.846119 | H11: =AGActual_Ratio*E11 -> 526.7863 | J11: WD-33-15 OIL PRODUCTION | L11: ='DATA INPUT'!E22 -> 5913 | M11: =L11-'DATA INPUT'!F22 -> 184 | N11: =L11*Actual_Ratio -> 5915.38 | O11: ='DATA INPUT'!E146-'DATA INPUT'!F146 -> 178.98546 | AU11: KHALDA_METER | AV11: =REPORTDATE-1 -> 46298 | AW11: 9AG GAS PLANT | AX11: P | AY11: OIL CORRECTION | AZ11: L | BA11: ='DATA INPUT'!E7 -> 0
B12: MAPLE-01, NAG & NEAG | C12: =IFERROR(IF(TDYPROD=0,0,COUNTIF(FIELD,"MAPLE")),"")+IFERROR(IF(TDYPROD=0,0,COUNTIF(FIELD,"NEAG")),"")+IFERROR(IF(TDYPROD=0,0,COUNTIF(FIELD,"NAG")),"") -> 5 | D12: =IFERROR(SUMIF(FIELD,"MAPLE",EST_GASPROD)*GAS_PROFAC,"")+IFERROR(SUMIF(FIELD,"MAPLE",GASLIFT)*GAS_PROFAC,"")+IFERROR(SUMIF(FIELD,"NEAG",EST_GASPROD)*GAS_PROFAC,"")+IFERROR(SUMIF(FIELD,"NEAG",GASLIFT)*GAS_PROFAC,"")+IFERROR(SUMIF(FIELD,"NAG",EST_GASPROD)*GAS_PROFAC,"")+IFERROR(SUMIF(FIELD,"NAG",GASLIFT)*GAS_PROFAC,"") -> 8.4731961 | E12: =IFERROR(SUMIF(FIELD,"MAPLE",EST_PROD)*OIL_PROFAC,"")+IFERROR(SUMIF(FIELD,"NEAG",EST_PROD)*OIL_PROFAC,"")+IFERROR(SUMIF(FIELD,"NAG",EST_PROD)*OIL_PROFAC,"") -> 1583.2851 | F12: 1618.9036 | G12: =IF(E12="","",E12-F12) -> -35.61849 | H12: =AGActual_Ratio*E12 -> 1583.9224 | J12: TOTAL AG PRODUCTION | L12: =SUM(L8:L11) -> 17684.651 | M12: =SUM(M8:M11) -> -9.0802529 | N12: =SUM(N8:N11) -> 17691.769 | O12: =SUM(O8:O11) -> -25.189253 | BC12: Add Meter: Summation of oil production of wells producing on SAG SEP
B13: MEGHAR & Reviera | C13: =IFERROR(IF(TDYPROD=0,0,COUNTIF(FIELD,"MEGHAR")),"")+IFERROR(IF(TDYPROD=0,0,COUNTIF(FIELD,"RIVIERA")),"") -> 3 | D13: =IFERROR(SUMIF(FIELD,"MEGHAR",EST_GASPROD)*GAS_PROFAC,"")+IFERROR(SUMIF(FIELD,"MEGHAR",GASLIFT)*GAS_PROFAC,"")+IFERROR(SUMIF(FIELD,"RIVIERA",EST_GASPROD)*GAS_PROFAC,"")+IFERROR(SUMIF(FIELD,"RIVIERA",GASLIFT)*GAS_PROFAC,"") -> 0.96018633 | E13: =IFERROR(SUMIF(FIELD,"MEGHAR",EST_PROD)*OIL_PROFAC,"")+IFERROR(SUMIF(FIELD,"RIVIERA",EST_PROD)*OIL_PROFAC,"") -> 34.812277 | F13: 25.709514 | G13: =IF(E13="","",E13-F13) -> 9.1027632 | H13: =AGActual_Ratio*E13 -> 34.826289 | J13: TOTAL AG PRODUCTION WITHOUT THIRD PARTY | L13: =L12-'DATA INPUT'!E6 -> 17630.345 | M13: =M11+M10+M8+((L9-'DATA INPUT'!E6)-('DATA INPUT'!F5-'DATA INPUT'!F6)) -> -10.661253 | N13: =L13*Actual_Ratio -> 17637.441 | O13: ='DATA INPUT'!E148-'DATA INPUT'!F148 -> -26.724058
B14: Mahroussa-D | C14: =IFERROR(IF(TDYPROD=0,0,COUNTIF(FIELD,"Mahroussa-D")),"") -> 1 | D14: =IFERROR(SUMIF(FIELD,"Mahroussa-D",EST_GASPROD)*GAS_PROFAC,"")+IFERROR(SUMIF(FIELD,"Mahroussa-D",GASLIFT)*GAS_PROFAC,"") -> 0 | E14: =IFERROR(SUMIF(FIELD,"Mahroussa-D",EST_PROD)*OIL_PROFAC,"") -> 47.414142 | F14: 48.480797 | G14: =IF(E14="","",E14-F14) -> -1.0666557 | H14: =AGActual_Ratio*E14 -> 47.433226 | J14: RAZZAK OIL PRODUCTION | L14: =+'DATA INPUT'!E9 -> 5540 | M14: ='DATA INPUT'!E9-'DATA INPUT'!F9 -> 40 | N14: =BB22 -> 5541.0732 | O14: ='DATA INPUT'!E150-'DATA INPUT'!F150 -> 39.72406
B15: WD09 (A, B &D, E) | C15: =IFERROR(IF(TDYPROD=0,0,COUNTIF(FIELD,"WD09-A")),"")+IFERROR(IF(TDYPROD=0,0,COUNTIF(FIELD,"WD09-B")),"")+IFERROR(IF(TDYPROD=0,0,COUNTIF(FIELD,"WD09-E")),"") -> 10 | D15: =IFERROR(SUMIF(FIELD,"WD09-A",EST_GASPROD)*GAS_PROFAC,"")+IFERROR(SUMIF(FIELD,"WD09-A",GASLIFT)*GAS_PROFAC,"")+IFERROR(SUMIF(FIELD,"WD09-B",EST_GASPROD)*GAS_PROFAC,"")+IFERROR(SUMIF(FIELD,"WD09-B",GASLIFT)*GAS_PROFAC,"")+IFERROR(SUMIF(FIELD,"WD09-E",GASLIFT)*GAS_PROFAC,"") -> 12.301137 | E15: =IFERROR(SUMIF(FIELD,"WD09-A",EST_PROD)*OIL_PROFAC,"")+IFERROR(SUMIF(FIELD,"WD09-b",EST_PROD)*OIL_PROFAC,"")+IFERROR(SUMIF(FIELD,"WD09-D",EST_PROD)*OIL_PROFAC,"")+IFERROR(SUMIF(FIELD,"WD09-E",EST_PROD)*OIL_PROFAC,"") -> 4133.291 | F15: 4204.4343 | G15: =IF(E15="","",E15-F15) -> -71.143275 | H15: =AGActual_Ratio*E15 -> 4134.9546 | J15: NWRZK OIL PRODUCTION | L15: =+'DATA INPUT'!E17 -> 105 | M15: =+'DATA INPUT'!E17-'DATA INPUT'!F17 -> 0 | N15: =BB23 -> 105.04219 | O15: ='DATA INPUT'!E152-'DATA INPUT'!F152 -> -0.096821092
B16: WD30 A | C16: =IFERROR(IF(TDYPROD=0,0,COUNTIF(FIELD,"WD30 A")),"") -> 1 | D16: =IFERROR(SUMIF(FIELD,"WD30 A",EST_GASPROD)*GAS_PROFAC,"")+IFERROR(SUMIF(FIELD,"WD30 A",GASLIFT)*GAS_PROFAC,"") -> 0.86228926 | E16: =IFERROR(SUMIF(FIELD,"WD30 a",EST_PROD)*OIL_PROFAC,"") -> 42.475169 | F16: 43.430714 | G16: =IF(E16="","",E16-F16) -> -0.95554575 | H16: =AGActual_Ratio*E16 -> 42.492265 | J16: NRQ OIL PRODUCTION | L16: ='DATA INPUT'!E11 -> 490 | M16: ='DATA INPUT'!E11-'DATA INPUT'!F11 -> -1 | N16: =BB26 -> 490.27728 | O16: ='DATA INPUT'!E151-'DATA INPUT'!F151 -> -1.3582209 | BI16: AVOCET TAG | BJ16: DATE | BK16: PLANT | BL16: TYPE | BM16: METER NAME | BN16: MT | BO16: LIQUID | BP16: GAS
B17: HAWK | C17: =IFERROR(IF(TDYPROD=0,0,COUNTIF(FIELD,"HAWK")),"") -> 3 | D17: =IFERROR(SUMIF(FIELD,"HAWK",EST_GASPROD)*GAS_PROFAC,"")+IFERROR(SUMIF(FIELD,"HAWK",GASLIFT)*GAS_PROFAC,"") -> 0.28157532 | E17: =IFERROR(SUMIF(FIELD,"HAWK",EST_PROD)*OIL_PROFAC,"") -> 1061.1409 | F17: 1085.0129 | G17: =IF(E17="","",E17-F17) -> -23.872033 | H17: =AGActual_Ratio*E17 -> 1061.568 | J17: NERZK OIL PRODUCTION | L17: =+'DATA INPUT'!E15 -> 123 | M17: ='DATA INPUT'!E15-'DATA INPUT'!F15 -> -1 | N17: =+BB29 -> 123.04943 | O17: ='DATA INPUT'!E155-'DATA INPUT'!F155 -> -1.114743 | AV17: Open | AW17: Received | AX17: Shipped | AY17: Close | BI17: KHALDA_METER | BJ17: =REPORTDATE-1 -> 46298 | BK17: 9AG OIL PLANT | BL17: B | BM17: AG OIL | BN17: L | BO17: =N8-'DATA INPUT'!E7 -> 10855.889
B18: SPYGLASS-W & SPYGLASS | C18: =IFERROR(IF(TDYPROD=0,0,COUNTIF(FIELD,"SPYGLASS-W")),"")+IFERROR(IF(TDYPROD=0,0,COUNTIF(FIELD,"SPYGLASS")),"") -> 2 | D18: =IFERROR(SUMIF(FIELD,"SPYGLASS-W",EST_GASPROD)*GAS_PROFAC,"")+IFERROR(SUMIF(FIELD,"SPYGLASS-W",GASLIFT)*GAS_PROFAC,"")+IFERROR(SUMIF(FIELD,"SPYGLASS",EST_GASPROD)*GAS_PROFAC,"")+IFERROR(SUMIF(FIELD,"SPYGLASS",GASLIFT)*GAS_PROFAC,"") -> 0.53728152 | E18: =IFERROR(SUMIF(FIELD,"SPYGLASS-W",EST_PROD)*OIL_PROFAC,"")+IFERROR(SUMIF(FIELD,"SPYGLASS",EST_PROD)*OIL_PROFAC,"") -> 108.23635 | F18: 113.97884 | G18: =IF(E18="","",E18-F18) -> -5.7424963 | H18: =AGActual_Ratio*E18 -> 108.27991 | J18: AKIK OIL PRODUCTION | L18: ='DATA INPUT'!E13 -> 195 | M18: ='DATA INPUT'!E13-'DATA INPUT'!F13 -> -1 | N18: =BB27 -> 195.07796 | O18: ='DATA INPUT'!E153-'DATA INPUT'!F153 -> -1.1762406 | AU18: Alamein | AV18: =G46 -> 56615.981 | AW18: =G50 -> 24177.712 | AX18: =G47 -> 23447.499 | AY18: =G49 -> 57346.194 | BA18: =AV18+AW18=AX18+AY18 -> TRUE | BI18: KHALDA_METER | BJ18: =REPORTDATE-1 -> 46298 | BM18: AG COND | BN18: L | BO18: =N9 -> 665.39671
B19: SHADOW & SHADOW-W , NW | C19: =IFERROR(IF(TDYPROD=0,0,COUNTIF(FIELD,"SHADOW")),"")+IFERROR(IF(TDYPROD=0,0,COUNTIF(FIELD,"shadow-W")),"")+IFERROR(IF(TDYPROD=0,0,COUNTIF(FIELD,"shadow-nW")),"") -> 7 | D19: =IFERROR(SUMIF(FIELD,"SHADOW",EST_GASPROD)*GAS_PROFAC,"")+IFERROR(SUMIF(FIELD,"SHADOW",GASLIFT)*GAS_PROFAC,"")+IFERROR(SUMIF(FIELD,"SHADOW-W",EST_GASPROD)*GAS_PROFAC,"")+IFERROR(SUMIF(FIELD,"SHADOW-W",GASLIFT)*GAS_PROFAC,"")+IFERROR(SUMIF(FIELD,"SHADOW-nW",GASLIFT)*GAS_PROFAC,"") -> 7.9437289 | E19: =IFERROR(SUMIF(FIELD,"SHADOW",EST_PROD)*OIL_PROFAC,"")+IFERROR(SUMIF(FIELD,"shadow-W",EST_PROD)*OIL_PROFAC,"")+IFERROR(SUMIF(FIELD,"shadow-nW",EST_PROD)*OIL_PROFAC,"") -> 577.40088 | F19: 591.11477 | G19: =IF(E19="","",E19-F19) -> -13.713897 | H19: =AGActual_Ratio*E19 -> 577.63328 | J19: RAFIKI OIL PRODUCTION | L19: =MOVEMENT!F43 -> 123 | M19: ='DATA INPUT'!E19-'DATA INPUT'!F19 -> 0 | N19: =BB28 -> 123.04943 | O19: ='DATA INPUT'!E154-'DATA INPUT'!F154 -> -0.11341899 | AZ19: =+L40/L39 -> 1.0004019 | BA19: =AV19+AW19=AX19+AY19 -> TRUE | BI19: KHALDA_METER | BJ19: =REPORTDATE-1 -> 46298 | BM19: RAFIKI | BN19: L | BO19: =N34 -> 123.04943
B20: OLYMPIC | C20: =IFERROR(IF(TDYPROD=0,0,COUNTIF(FIELD,"OLYMPIC")),"") -> 1 | D20: =IFERROR(SUMIF(FIELD,"OLYMPIC",EST_GASPROD)*GAS_PROFAC,"")+IFERROR(SUMIF(FIELD,"OLYMPIC",GASLIFT)*GAS_PROFAC,"") -> 0 | E20: =IFERROR(SUMIF(FIELD,"OLYMPIC",EST_PROD)*OIL_PROFAC,"") -> 179.68882 | F20: 183.7312 | G20: =IF(E20="","",E20-F20) -> -4.0423828 | H20: =AGActual_Ratio*E20 -> 179.76115 | J20: TOTAL RAZZAK PRODUCTION | L20: =SUM(L14:L19) -> 6576 | M20: =SUM(M14:M19) -> 37 | N20: =SUM(N14:N19) -> 6577.5695 | O20: =SUM(O14:O19) -> 35.864616 | AW20: Prod | AX20: Shipped | AY20: Close | AZ20: Reconciled Shipped | BB20: Reconciled Prod | BI20: KHALDA_METER | BJ20: =REPORTDATE-1 -> 46298 | BM20: NWRZK | BN20: L | BO20: =N32 -> 105.04219
B21: PACIFIC | C21: =IFERROR(IF(TDYPROD=0,0,COUNTIF(FIELD,"PACIFIC")),"") -> 0 | D21: =IFERROR(SUMIF(FIELD,"PACIFIC",EST_GASPROD)*GAS_PROFAC,"")+IFERROR(SUMIF(FIELD,"PACIFIC",GASLIFT)*GAS_PROFAC,"") -> 0 | E21: =IFERROR(SUMIF(FIELD,"PACIFIC",EST_PROD)*OIL_PROFAC,"") -> 0 | F21: 0 | G21: =IF(E21="","",E21-F21) -> 0 | H21: =AGActual_Ratio*E21 -> 0 | J21: WATER INJECTION SUMMARY | AU21: AG | AV21: =G35 -> 20791.186 | AW21: =G39 -> 17755.651 | AX21: =TOTPUMPED -> 17774 | AY21: =G38 -> 20772.837 | AZ21: =$AZ$19*AX21 -> 17781.143 | BA21: =AV21+AW21=AX21+AY21 -> TRUE | BB21: =AZ21+AY21-AV21 -> 17762.793 | BI21: KHALDA_METER | BJ21: =REPORTDATE-1 -> 46298 | BM21: AKIK-NE | BN21: L | BO21: =N33 -> 194.07796
B22: RIDGEWOOD | C22: =IFERROR(IF(TDYPROD=0,0,COUNTIF(FIELD,"RIDGEWOOD")),"") -> 1 | D22: =IFERROR(SUMIF(FIELD,"RIDGEWOOD",EST_GASPROD)*GAS_PROFAC,"")+IFERROR(SUMIF(FIELD,"RIDGEWOOD",GASLIFT)*GAS_PROFAC,"") -> 1.0480852 | E22: =IFERROR(SUMIF(FIELD,"RIDGEWOOD",EST_PROD)*OIL_PROFAC,"") -> 64.20665 | F22: 65.65108 | G22: =IF(E22="","",E22-F22) -> -1.4444296 | H22: =AGActual_Ratio*E22 -> 64.232493 | J22: AREA | K22: WATER INJ | L22: WATER INJ TARGET | N22: DELTA | AU22: RZK | AV22: ='DATA INPUT'!F8 -> 31660 | AW22: =L14 -> 5540 | AX22: =L28 -> 5159 | AY22: ='DATA INPUT'!E8 -> 32040 | AZ22: =$AZ$19*AX22 -> 5161.0732 | BA22: =AV22+AW22=AX22+AY22 -> FALSE | BB22: =AZ22+AY22-AV22 -> 5541.0732 | BI22: KHALDA_METER | BJ22: =REPORTDATE-1 -> 46298 | BM22: NORTH RAS QATTARA | BN22: L | BO22: =N31 -> 690.27728
B23: WD33 | C23: =IFERROR(IF(TDYPROD=0,0,COUNTIF(FIELD,"WD33")),"")+IFERROR(IF(TDYPROD=0,0,COUNTIF(FIELD,"WD33 v")),"") -> 5 | D23: 0 | E23: =IFERROR(SUMIF(FIELD,"WD33",EST_PROD)*OIL_PROFAC3,"")+IFERROR(SUMIF(FIELD,"WD33 v",EST_PROD)*OIL_PROFAC3,"") -> 255 | F23: 253 | G23: =IF(E23="","",E23-F23) -> 2 | H23: =AGActual_Ratio*E23 -> 255.10264 | J23: RAZZAK AREA | K23: ='WATER FLOOD WELLS'!D65 -> 55989 | L23: ='WATER FLOOD WELLS'!C65 -> 64650 | N23: ='WATER FLOOD WELLS'!E65 -> -8661 | AU23: NWRZK | AW23: =+'DATA INPUT'!E17 -> 105 | AX23: =+'DATA INPUT'!E18 -> 105 | AZ23: =$AZ$19*AX23 -> 105.04219 | BA23: =AV23+AW23=AX23+AY23 -> TRUE | BB23: =AW23+(AZ23-AX23) -> 105.04219 | BI23: KHALDA_METER | BJ23: =REPORTDATE-1 -> 46298 | BM23: ENPEDCO | BN23: L | BO23: ='OAPCO FAX'!E13 -> 0
B24: WD33-15 | C24: =IFERROR(IF(TDYPROD=0,0,COUNTIF(FIELD,"WD33-15")),"")+IFERROR(IF(TDYPROD=0,0,COUNTIF(FIELD,"WD-33K")),"")+IFERROR(IF(TDYPROD=0,0,COUNTIF(FIELD,"WD33 H")),"")+IFERROR(IF(TDYPROD=0,0,COUNTIF(FIELD,"WD33-C")),"")+IFERROR(IF(TDYPROD=0,0,COUNTIF(FIELD,"WD33 j")),"") -> 10 | D24: 0 | E24: =IFERROR(SUMIF(FIELD,"WD33-15",EST_PROD)*OIL_PROFAC2,"")+IFERROR(SUMIF(FIELD,"WD33-c",EST_PROD)*OIL_PROFAC2,"")+IFERROR(SUMIF(FIELD,"WD33 H",EST_PROD)*OIL_PROFAC2,"")+IFERROR(SUMIF(FIELD,"WD-33k",EST_PROD)*OIL_PROFAC2,"")+IFERROR(SUMIF(FIELD,"WD33 j",EST_PROD)*OIL_PROFAC2,"") -> 5913 | F24: 5729 | G24: =IF(E24="","",E24-F24) -> 184 | H24: =AGActual_Ratio*E24 -> 5915.38 | J24: AG AREA | K24: ='WATER FLOOD WELLS'!D79 -> 27650 | L24: ='WATER FLOOD WELLS'!C79 -> 34850 | N24: ='WATER FLOOD WELLS'!E79 -> -7163 | AU24: ENPEDCO | AX24: =+'DATA INPUT'!E7 -> 0 | AZ24: =$AZ$19*AX24 -> 0 | BA24: =AV25+AW25=AX25+AY25 -> TRUE | BB24: =AY25+AZ25-AV25 -> 5915.4047 | BI24: KHALDA_METER | BJ24: =REPORTDATE-1 -> 46298 | BM24: WD-33 OIL | BN24: L | BO24: =N10 -> 255.10264
B25: TOTAL | C25: =IFERROR(SUM(C6:C24),0) -> 83 | D25: =IFERROR(SUM(D6:D24),0) -> 56.799567 | E25: =IFERROR(SUM(E6:E24),0) -> 17019.522 | F25: 17034.389 | G25: =IF(E25="","",E25-F25) -> -14.867215 | H25: =SUM(H7:H24) -> 17026.372 | J25: TOTAL INJ WATER | K25: =SUM(K23:K24) -> 83639 | L25: =SUM(L23:M24) -> 99500 | N25: =SUM(N23:N24) -> -15824 | AU25: WD | AV25: =D56 -> 1342 | AW25: =D57 -> 5913 | AX25: =D58 -> 5984 | AY25: =D59 -> 1271 | AZ25: =$AZ$19*AX25 -> 5986.4047 | BA25: =AV26+AW26=AX26+AY26 -> FALSE | BB25: =AW28+(AZ28-AX28) -> 123.04943 | BI25: KHALDA_METER | BJ25: =REPORTDATE-1 -> 46298 | BM25: WD-33-15 OIL | BN25: L
B26: SAG SEP | E26: 0 | F26: 0 | G26: =IF(E26="","",E26-F26) -> 0 | H26: =E26 -> 0 | J26: SHIPPING SUMMARY | N26: Received | AU26: GPC | AX26: =+L38 -> 123 | BA26: =AV27+AW27=AX27+AY27 -> FALSE | BB26: =AW27+(AZ27-AX27) -> 490.27728 | BI26: KHALDA_METER | BJ26: =REPORTDATE-1 -> 46298 | BM26: AG-157 GL | BN26: O | BP26: ='WELL DATA'!H83 -> 1.44
B27: TOTAL OIL | E27: =IFERROR(SUM(E25:E26),0) -> 17019.522 | F27: 17034.389 | G27: =E27-F27 -> -14.867215 | H27: =N8+N10+N11 -> 17026.372 | J27: AG SHIPPED OIL | L27: =H36 -> 17774 | M27: BBL | N27: =$AZ$19*L27 -> 17781.143 | AU27: NRQ | AV27: 0 | AW27: =L16 -> 490 | AX27: =L31 -> 690 | AY27: 0 | AZ27: =$AZ$19*AX27 -> 690.27728 | BA27: =AV29+AW29=AX29+AY29 -> FALSE | BB27: =AW29+(AZ29-AX29) -> 195.07796 | BI27: KHALDA_METER | BJ27: =REPORTDATE-1 -> 46298 | BM27: AG-108 GL | BN27: O | BP27: ='WELL DATA'!H60 -> 0
J28: RAZZAK SHIPPED OIL | L28: ='DATA INPUT'!E10 -> 5159 | M28: BBL | N28: =AZ22 -> 5161.0732 | AU28: NERZK | AW28: =+'DATA INPUT'!E15 -> 123 | AX28: =+'DATA INPUT'!E16 -> 123 | AZ28: =$AZ$19*AX28 -> 123.04943 | BA28: =AV31+AW31=AX31+AY31 -> TRUE | BB28: =AW31+(AZ31-AX31) -> 123.04943 | BI28: KHALDA_METER | BJ28: =REPORTDATE-1 -> 46298 | BM28: AG-117STGL | BN28: O | BP28: ='WELL DATA'!H64 -> 0
J29: WD-33-15 SHIPPED OIL | L29: ='DATA INPUT'!E21 -> 5984 | M29: BBL | N29: =AZ25 -> 5986.4047 | AU29: AKIK-NE | AW29: =+'DATA INPUT'!E13 -> 195 | AX29: =+'DATA INPUT'!E14 -> 194 | AZ29: =$AZ$19*AX29 -> 194.07796 | BB29: =AW28+(AZ28-AX28) -> 123.04943 | BI29: KHALDA_METER | BJ29: =REPORTDATE-1 -> 46298 | BM29: AG-146 GL | BN29: O | BP29: ='WELL DATA'!H80 -> 0
J30: WD-33 SHIPPED OIL | L30: ='DATA INPUT'!E24 -> 255 | M30: BBL | N30: =AZ30 -> 255.10247 | AU30: WD-33 | AV30: ='DATA INPUT'!F25 -> 159 | AW30: ='DATA INPUT'!E26 -> 255 | AX30: ='DATA INPUT'!E24 -> 255 | AY30: ='DATA INPUT'!E25 -> 159 | AZ30: =$AZ$19*AX30 -> 255.10247 | BB30: =AY30+AZ30-AV30 -> 255.10247 | BI30: KHALDA_METER | BJ30: =REPORTDATE-1 -> 46298 | BM30: AG-119 GL | BN30: O | BP30: ='WELL DATA'!H66 -> 0
J31: NRQ SHIPPED OIL | L31: ='DATA INPUT'!NRQSHIPPED -> 690 | M31: BBL | N31: =AZ27 -> 690.27728 | AU31: RAFIKI | AV31: =MOVEMENT!F42 -> 0 | AW31: =MOVEMENT!F43 -> 123 | AX31: =MOVEMENT!F44 -> 123 | AY31: =MOVEMENT!F45 -> 0 | AZ31: =$AZ$19*AX31 -> 123.04943 | BI31: KHALDA_METER | BJ31: =REPORTDATE-1 -> 46298 | BM31: AG-125 GL | BN31: O | BP31: ='WELL DATA'!H70 -> 0
B32: PRODUCTION TANK SUMMARY | J32: NWRZK SHIPPED OIL | L32: =+'DATA INPUT'!E18 -> 105 | M32: BBL | N32: =+AZ23 -> 105.04219 | AU32: TAG | AX32: =+'DATA INPUT'!E31 -> 0 | AZ32: =$AZ$19*AX32 -> 0 | BI32: KHALDA_METER | BJ32: =REPORTDATE-1 -> 46298 | BM32: AG-141 GL | BN32: O | BP32: =+'WELL DATA'!H77 -> 1.24
B33: ITEM | D33: TANK 201 | E33: TANK 202 | F33: POWER OIL | G33: TOTALS | H33: TOTALS WITHOUT OIL RECEIVED FROM OFFLOADING STATION | J33: AKIK SHIPPED OIL | L33: ='DATA INPUT'!E14 -> 194 | M33: BBL | N33: =+AZ29 -> 194.07796 | AU33: BOLT | AX33: =+L37 -> 47 | AZ33: =+AX33*$AZ$19 -> 47.018887 | BI33: KHALDA_METER | BJ33: =REPORTDATE-1 -> 46298 | BM33: RIDGEWOOD-01 GL | BN33: O | BP33: ='WELL DATA'!H117 -> 1.0493882
B34: Tank Status | D34: =IFERROR(IF(D38-D35>0,"Production",IF(D38-D35<0,"Shipping",IF(D38-D35=0,"Closed"))),"") -> Shipping | E34: =IFERROR(IF(E38-E35>0,"Production",IF(E38-E35<0,"Shipping",IF(E38-E35=0,"Closed"))),"") -> Production | F34: =IFERROR(IF(F38-F35>0,"Production",IF(F38-F35<0,"Shipping",IF(F38-F35=0,"Closed"))),"") -> Closed | J34: RAFIKI SHIPPED OIL | L34: ='DATA INPUT'!E20 -> 123 | M34: BBL | N34: =+AZ31 -> 123.04943 | AW34: =AW21+AW22+AW23+AW27+AW29+AW31 -> 24208.651 | AX34: =AX21+AX22+AX23+AX26+AX27+AX29+AX31+AX33 -> 24215 | AY34: 0 | AZ34: =AZ19*L32 -> 105.04219 | BI34: KHALDA_METER | BJ34: =REPORTDATE-1 -> 46298 | BM34: SWAG-N01 GL | BN34: O | BP34: ='WELL DATA'!H148 -> 1.4670939
B35: Opening Stock | D35: =IFERROR(TANKS!E3,"") -> 19313.4 | E35: =IFERROR(TANKS!E5,"") -> 1477.7861 | F35: =IFERROR(TANKS!E7,"") -> 0 | G35: =SUM(OPENINGSTK) -> 20791.186 | H35: =SUM(OPENINGSTK) -> 20791.186 | J35: ENPEDCO | L35: =+'DATA INPUT'!E7 -> 0 | M35: BBL | N35: =+AZ24 -> 0 | BI35: KHALDA_METER | BJ35: =REPORTDATE-1 -> 46298 | BM35: AG-13 GL | BN35: O | BP35: ='WELL DATA'!H9 -> 0.95949584
B36: Net Pumped | D36: =IFERROR(TANKS!M3,"") -> 17774 | E36: =IFERROR(TANKS!M5,"") -> 0 | F36: =IFERROR(TANKS!M7,"") -> 0 | G36: =SUM(SHIPPED) -> 17774 | H36: =SUM(SHIPPED)-'DATA INPUT'!E7-'DATA INPUT'!E31 -> 17774 | J36: OIL FROM TAG | L36: ='DATA INPUT'!E31 -> 0 | M36: BBL | N36: =AZ32 -> 0 | BI36: KHALDA_METER | BJ36: =REPORTDATE-1 -> 46298 | BM36: AG-15 GL | BN36: O | BP36: ='WELL DATA'!H11 -> 0
B37: Water Drained | D37: =IFERROR(TANKS!N3,"") -> 24 | E37: =IFERROR(TANKS!N5,"") -> 0 | F37: =IFERROR(TANKS!N7,"") -> 0 | G37: =SUM(WATERDRAIN) -> 24 | H37: =SUM(WATERDRAIN) -> 24 | J37: OIL FROM BOLT | L37: =+'DATA INPUT'!E32 -> 47 | M37: BBL | N37: =+AZ33 -> 47.018887 | BI37: KHALDA_METER | BJ37: =REPORTDATE-1 -> 46298 | BM37: AG-130 GL | BN37: O | BP37: ='WELL DATA'!H71 -> 0
B38: Closing Stock | D38: =IFERROR(TANKS!E4,"") -> 1515.3428 | E38: =IFERROR(TANKS!E6,"") -> 19257.494 | F38: =IFERROR(TANKS!E8,"") -> 0 | G38: =SUM(CLOSINGSTK) -> 20772.837 | H38: =SUM(CLOSINGSTK) -> 20772.837 | J38: OIL FROM NERZK-A | L38: =+'DATA INPUT'!E16 -> 123 | M38: BBL | N38: =+AZ28 -> 123.04943 | BI38: KHALDA_METER | BJ38: =REPORTDATE-1 -> 46298 | BM38: AG-110 GL | BN38: O | BP38: ='WELL DATA'!H61 -> 0
B39: PRODUCTION | G39: =IFERROR(IF((G38+G36-G35)<0,G37*-1,(G38+G36-G35)),0) -> 17755.651 | H39: =IFERROR(IF((H38+H36-H35)<0,H37*-1,(H38+H36-H35)),0) -> 17755.651 | J39: OIL SHIPPED TO ALAMEIN | L39: =SUM(L27,L28,L31,L32,L33,L34,L35,L36,L38) -> 24168 | M39: BBL | N39: Month to Date Cum | BI39: KHALDA_METER | BJ39: =REPORTDATE-1 -> 46298 | BM39: AG-24 GL | BN39: O | BP39: ='WELL DATA'!H15 -> 0
B40: Temperature (°F) | D40: ='DATA INPUT'!E37 -> 97 | E40: ='DATA INPUT'!E45 -> 97 | F40: ='DATA INPUT'!E53 -> 0 | J40: OIL RECEIVED AT ALAMEIN | L40: =G50 -> 24177.712 | M40: BBL | BI40: KHALDA_METER | BJ40: =REPORTDATE-1 -> 46298 | BM40: AG-25ST1 GL | BN40: O | BP40: ='WELL DATA'!H16 -> 0
...

Sheet WELL TESTS
B1: WELL TESTS | Y1: =REPDATE -> 46299 | AU1: =COUNTIF(DATATAG,"KHALDA_WELLTEST1") -> 7 | AW1: ="Ar4"&":"&"Bh"&COUNTIF(DATATAG,"<>0")+3 -> Ar4:Bh10
B2: TEST FACILITY | C2: WELL NAME | D2: ZONE | E2: STATUS | F2: CHOKE 64" | G2: WHP PSI | H2: WHT °F | I2: SEP PSI | J2: BFBD STB | K2: BS&W % | L2: BOPD STB | M2: GAS MMSCFD | N2: GAS LIFT MMSCFD | O2: GOR scf/bbl | P2: HRS ON TEST | Q2: DFL | R2: NLAP | S2: PIP | T2: FREQUENCY | U2: CSG PSI | V2: CSG STATUS | W2: CL, PPM | X2: COMMENTS | Z2: TYPE | AR2: RECORD | AS2: DATE | AT2: TEST SEQUENCE | AU2: WELL | AV2: HOURS | AW2: TYPE | AX2: BFPD | AY2: GAS | AZ2: CHOKE | BA2: WHP | BB2: WHT | BC2: SEP | BD2: DFL | BE2: NLAP | BF2: BSW | BG2: PIP | BH2: FREQUENCY | BI2: LIQ TYPE | BJ2: GAS LIFT | BK2: CL, PPM
L3: =IF(WELLNAME="","",(FLUIDTOTAL*(1-(WC/100)))) -> #VALUE! | O3: =IF(WELLNAME="","",IF(GAS=0,0,(GAS*1000000)/OIL)) -> #VALUE! | AR3: =IF(C3="",0,"KHALDA_WELLTEST2") -> 0 | AS3: =IF(AR3="","",REPORTDATE-1) -> 46298 | AU3: =UPPER(IF(AR3="","",$AQ$4&C3)) -> 9 | AV3: =IF(AR3="","",P3) -> 0 | AW3: =IF(AR3=0,0,1) -> 0 | AX3: =IF(AR3="","",J3) -> 0 | AY3: =IF(AR3="","",M3*1000) -> 0 | AZ3: =IF(AR3="","",F3) -> 0 | BA3: =IF(AR3="","",G3) -> 0 | BC3: =IF(AR3="","",I3) -> 0 | BD3: =IF(AR3="","",Q3) -> 0 | BE3: =IF(AR3="","",R3) -> 0 | BF3: =IF(AR3="","",K3) -> 0 | BI3: =IF(AR3=0,"",200) | BJ3: =N3 -> 0
C4: MAHROUSSA-A02 | D4: ARC | E4: G.W | F4: N/A | G4: 860 | H4: 188 | I4: 792 | J4: 170 | K4: 22 | L4: =IF(WELLNAME="","",(FLUIDTOTAL*(1-(WC/100)))) -> 132.6 | M4: 14.241 | N4: 0 | O4: =IF(WELLNAME="","",IF(GAS=0,0,(GAS*1000000)/OIL)) -> 107398.19 | P4: 5.5 | Q4: 0 | R4: 0 | U4: 0 / Closed | X4: BS&W F/ MTU & Lab H2S = 8 PPM, CO2 = 4 %, API= 47, M.F = 0.54 PICO-04 | AQ4: 9 | AR4: =IF(C4="",0,"KHALDA_WELLTEST1") -> KHALDA_WELLTEST1 | AS4: =IF(AR4="","",REPORTDATE-1) -> 46298 | AT4: =UPPER(IF(AR4="","",$AQ$4&C4)) -> 9MAHROUSSA-A02 | AU4: =UPPER(IF(AR4="","",$AQ$4&C4)) -> 9MAHROUSSA-A02 | AV4: =IF(AR4="","",P4) -> 5.5 | AW4: =IF(AR4=0,0,Z4) -> 0 | AX4: =IF(AR4="","",J4) -> 170 | AY4: =IF(AR4="","",M4*1000) -> 14241 | AZ4: =IF(AR4="","",F4) -> N/A | BA4: =IF(AR4="","",G4) -> 860 | BB4: =IF(AR4="","",H4) -> 188 | BC4: =IF(AR4="","",I4) -> 792 | BD4: =IF(AR4="","",Q4) -> 0 | BE4: =IF(AR4="","",R4) -> 0 | BF4: =IF(AR4="","",K4) -> 22 | BI4: =IF(AR4=0,"",200) -> 200 | BJ4: =N4 -> 0 | BK4: =IF(AR4="","",W4) -> 0
C5: AG-158 | D5: AR/G | E5: G.L | F5: No P.ch | G5: 220 | H5: 80 | I5: 210 | J5: 43 | K5: 20 | L5: =IF(WELLNAME="","",(FLUIDTOTAL*(1-(WC/100)))) -> 34.4 | M5: 0.034 | N5: 1.009 | O5: =IF(WELLNAME="","",IF(GAS=0,0,(GAS*1000000)/OIL)) -> 988.37209 | P5: 6 | Q5: 0 | R5: 0 | U5: 0 | X5: Flowing-PBU survey On GI 1 MMSCFD BS&W F/ Lab = 20 % & F/ MTU = 12 % M.F= 1, H2S = 1 PPM, CO2 = 4 %, API = 34 AL Mansoori-03 | AR5: =IF(C5="",0,"KHALDA_WELLTEST1") -> KHALDA_WELLTEST1 | AS5: =IF(AR5="","",REPORTDATE-1) -> 46298 | AT5: =UPPER(IF(AR5="","",$AQ$4&C5)) -> 9AG-158 | AU5: =UPPER(IF(AR5="","",$AQ$4&C5)) -> 9AG-158 | AV5: =IF(AR5="","",P5) -> 6 | AW5: =IF(AR5=0,0,Z5) -> 0 | AX5: =IF(AR5="","",J5) -> 43 | AY5: =IF(AR5="","",M5*1000) -> 34 | AZ5: =IF(AR5="","",F5) -> No P.ch | BA5: =IF(AR5="","",G5) -> 220 | BB5: =IF(AR5="","",H5) -> 80 | BC5: =IF(AR5="","",I5) -> 210 | BD5: =IF(AR5="","",Q5) -> 0 | BE5: =IF(AR5="","",R5) -> 0 | BF5: =IF(AR5="","",K5) -> 20 | BI5: =IF(AR5=0,"",200) -> 200 | BJ5: =N5 -> 1.009 | BK5: =IF(AR5="","",W5) -> 0
C6: MAHROUSSA-A01X | D6: ARC-BTM | E6: G.W | F6: F-Open | G6: 629 | H6: 174 | I6: 548 | J6: 131 | K6: 22 | L6: =IF(WELLNAME="","",(FLUIDTOTAL*(1-(WC/100)))) -> 102.18 | M6: 11.163 | N6: 0 | O6: =IF(WELLNAME="","",IF(GAS=0,0,(GAS*1000000)/OIL)) -> 109248.39 | P6: 8.5 | Q6: 0 | R6: 0 | U6: 0 Closed | X6: BS&W F/ MTU & Lab H2S = 10 PPM, CO2 = 4 %, API = 46 , M.F= 0.54 PICO-04 | AR6: =IF(C6="",0,"KHALDA_WELLTEST1") -> KHALDA_WELLTEST1 | AS6: =IF(AR6="","",REPORTDATE-1) -> 46298 | AT6: =UPPER(IF(AR6="","",$AQ$4&C6)) -> 9MAHROUSSA-A01X | AU6: =UPPER(IF(AR6="","",$AQ$4&C6)) -> 9MAHROUSSA-A01X | AV6: =IF(AR6="","",P6) -> 8.5 | AW6: =IF(AR6=0,0,Z6) -> 0 | AX6: =IF(AR6="","",J6) -> 131 | AY6: =IF(AR6="","",M6*1000) -> 11163 | AZ6: =IF(AR6="","",F6) -> F-Open | BA6: =IF(AR6="","",G6) -> 629 | BB6: =IF(AR6="","",H6) -> 174 | BC6: =IF(AR6="","",I6) -> 548 | BD6: =IF(AR6="","",Q6) -> 0 | BE6: =IF(AR6="","",R6) -> 0 | BF6: =IF(AR6="","",K6) -> 22 | BI6: =IF(AR6=0,"",200) -> 200 | BJ6: =N6 -> 0 | BK6: =IF(AR6="","",W6) -> 0
C7: SPYGLASS-02 | D7: ARG , E , C | E7: N.F | F7: 24/64 | G7: 80-120 | H7: 75 | I7: 3 | J7: 146 | K7: 25.7 | L7: =IF(WELLNAME="","",(FLUIDTOTAL*(1-(WC/100)))) -> 108.478 | M7: 0.389 | N7: 0 | O7: =IF(WELLNAME="","",IF(GAS=0,0,(GAS*1000000)/OIL)) -> 3585.9806 | P7: 24 | Q7: 0 | R7: 0 | U7: 0 | X7: (Min. press., Liq. T/ tank & gas flare) Choking back WHP via 2" globe vlv on MTU inlet. BS&W F/ MTU & Lab CO2 = 2 %, H2S=0 PPM, MF=1 , CL=53 KPPM Tanmia-09 | AR7: =IF(C7="",0,"KHALDA_WELLTEST1") -> KHALDA_WELLTEST1 | AS7: =IF(AR7="","",REPORTDATE-1) -> 46298 | AT7: =UPPER(IF(AR7="","",$AQ$4&C7)) -> 9SPYGLASS-02 | AU7: =UPPER(IF(AR7="","",$AQ$4&C7)) -> 9SPYGLASS-02 | AV7: =IF(AR7="","",P7) -> 24 | AW7: =IF(AR7=0,0,Z7) -> 0 | AX7: =IF(AR7="","",J7) -> 146 | AY7: =IF(AR7="","",M7*1000) -> 389 | AZ7: =IF(AR7="","",F7) -> 24/64 | BA7: =IF(AR7="","",G7) -> 80-120 | BB7: =IF(AR7="","",H7) -> 75 | BC7: =IF(AR7="","",I7) -> 3 | BD7: =IF(AR7="","",Q7) -> 0 | BE7: =IF(AR7="","",R7) -> 0 | BF7: =IF(AR7="","",K7) -> 25.7 | BI7: =IF(AR7=0,"",200) -> 200 | BJ7: =N7 -> 0 | BK7: =IF(AR7="","",W7) -> 0
C8: AG-115H | D8: ARD | E8: G.L | F8: N/A | G8: 50 | H8: 102 | I8: 30 | J8: 816 | K8: 34.1 | L8: =IF(WELLNAME="","",(FLUIDTOTAL*(1-(WC/100)))) -> 537.744 | M8: 0.895 | N8: 0.735 | O8: =IF(WELLNAME="","",IF(GAS=0,0,(GAS*1000000)/OIL)) -> 1664.3607 | P8: 24 | Q8: 0 | R8: 0 | U8: 0 | X8: (Min. press., Liq. T/ tank & gas partially T/ prod.) BS&W F/ MTU& lab. H2S= 5 PPM, CO2= 3 %, API= 37 , M.F= 1 "Gas to production line +/- 1.254 MMSCFD" Sigma ZFU | AR8: =IF(C8="",0,"KHALDA_WELLTEST1") -> KHALDA_WELLTEST1 | AS8: =IF(AR8="","",REPORTDATE-1) -> 46298 | AT8: =UPPER(IF(AR8="","",$AQ$4&C8)) -> 9AG-115H | AU8: =UPPER(IF(AR8="","",$AQ$4&C8)) -> 9AG-115H | AV8: =IF(AR8="","",P8) -> 24 | AW8: =IF(AR8=0,0,Z8) -> 0 | AX8: =IF(AR8="","",J8) -> 816 | AY8: =IF(AR8="","",M8*1000) -> 895 | AZ8: =IF(AR8="","",F8) -> N/A | BA8: =IF(AR8="","",G8) -> 50 | BB8: =IF(AR8="","",H8) -> 102 | BC8: =IF(AR8="","",I8) -> 30 | BD8: =IF(AR8="","",Q8) -> 0 | BE8: =IF(AR8="","",R8) -> 0 | BF8: =IF(AR8="","",K8) -> 34.1 | BI8: =IF(AR8=0,"",200) -> 200 | BJ8: =N8 -> 0.735 | BK8: =IF(AR8="","",W8) -> 0
C9: SHADOW-E08 | D9: ARE | E9: G.L | F9: Open | G9: 70 | H9: 100 | I9: 40 | J9: 234 | K9: 29 | L9: =IF(WELLNAME="","",(FLUIDTOTAL*(1-(WC/100)))) -> 166.14 | M9: 0.335 | N9: 1.2 | O9: =IF(WELLNAME="","",IF(GAS=0,0,(GAS*1000000)/OIL)) -> 2016.3717 | P9: 24 | Q9: 0 | R9: 0 | U9: 0 | X9: (Min. press., Liq. T/ tank & gas partially T/ prod.) IG = 1.2 MMSCFD BS&W F/ MTU & lab H2S= 3 PPM, CO2= 4 %, API=34, M.F=1 "Gas to production line +/- 1.477 MMSCFD" Sigma Fixed ZFU | AR9: =IF(C9="",0,"KHALDA_WELLTEST1") -> KHALDA_WELLTEST1 | AS9: =IF(AR9="","",REPORTDATE-1) -> 46298 | AT9: =UPPER(IF(AR9="","",$AQ$4&C9)) -> 9SHADOW-E08 | AU9: =UPPER(IF(AR9="","",$AQ$4&C9)) -> 9SHADOW-E08 | AV9: =IF(AR9="","",P9) -> 24 | AW9: =IF(AR9=0,0,Z9) -> 0 | AX9: =IF(AR9="","",J9) -> 234 | AY9: =IF(AR9="","",M9*1000) -> 335 | AZ9: =IF(AR9="","",F9) -> Open | BA9: =IF(AR9="","",G9) -> 70 | BB9: =IF(AR9="","",H9) -> 100 | BC9: =IF(AR9="","",I9) -> 40 | BD9: =IF(AR9="","",Q9) -> 0 | BE9: =IF(AR9="","",R9) -> 0 | BF9: =IF(AR9="","",K9) -> 29 | BI9: =IF(AR9=0,"",200) -> 200 | BJ9: =N9 -> 1.2 | BK9: =IF(AR9="","",W9) -> 0
C10: WD33-15-11 | D10: ARC | E10: ESP | F10: F.Open | G10: 175 | H10: 150 | I10: 120 | J10: 3289 | K10: 83 | L10: =IF(WELLNAME="","",(FLUIDTOTAL*(1-(WC/100)))) -> 559.13 | M10: 0 | N10: 0 | O10: =IF(WELLNAME="","",IF(GAS=0,0,(GAS*1000000)/OIL)) -> 0 | P10: 5 | Q10: 0 | R10: 521-525 | U10: 0 to flare. | X10: On Freq 55 HZ BS&W F/ MTU & lab API= 35, MF= 0.93 , CL= 68 KPPM, CO2= 3 %, H2S = 0 PPM AL Mansoori-04 | AR10: =IF(C10="",0,"KHALDA_WELLTEST1") -> KHALDA_WELLTEST1 | AS10: =IF(AR10="","",REPORTDATE-1) -> 46298 | AT10: =UPPER(IF(AR10="","",$AQ$4&C10)) -> 9WD33-15-11 | AU10: =UPPER(IF(AR10="","",$AQ$4&C10)) -> 9WD33-15-11 | AV10: =IF(AR10="","",P10) -> 5 | AW10: =IF(AR10=0,0,Z10) -> 0 | AX10: =IF(AR10="","",J10) -> 3289 | AY10: =IF(AR10="","",M10*1000) -> 0 | AZ10: =IF(AR10="","",F10) -> F.Open | BA10: =IF(AR10="","",G10) -> 175 | BB10: =IF(AR10="","",H10) -> 150 | BC10: =IF(AR10="","",I10) -> 120 | BD10: =IF(AR10="","",Q10) -> 0 | BE10: =IF(AR10="","",R10) -> 521-525 | BF10: =IF(AR10="","",K10) -> 83 | BI10: =IF(AR10=0,"",200) -> 200 | BJ10: =N10 -> 0 | BK10: =IF(AR10="","",W10) -> 0
L11: =IF(WELLNAME="","",(FLUIDTOTAL*(1-(WC/100)))) | O11: =IF(WELLNAME="","",IF(GAS=0,0,(GAS*1000000)/OIL)) | AR11: =IF(C11="",0,"KHALDA_WELLTEST1") -> 0 | AS11: =IF(AR11="","",REPORTDATE-1) -> 46298 | AT11: =UPPER(IF(AR11="","",$AQ$4&C11)) -> 9 | AU11: =UPPER(IF(AR11="","",$AQ$4&C11)) -> 9 | AV11: =IF(AR11="","",P11) -> 0 | AW11: =IF(AR11=0,0,Z11) -> 0 | AX11: =IF(AR11="","",J11) -> 0 | AY11: =IF(AR11="","",M11*1000) -> 0 | AZ11: =IF(AR11="","",F11) -> 0 | BA11: =IF(AR11="","",G11) -> 0 | BB11: =IF(AR11="","",H11) -> 0 | BC11: =IF(AR11="","",I11) -> 0 | BD11: =IF(AR11="","",Q11) -> 0 | BE11: =IF(AR11="","",R11) -> 0 | BF11: =IF(AR11="","",K11) -> 0 | BI11: =IF(AR11=0,"",200) | BJ11: =N11 -> 0 | BK11: =IF(AR11="","",W11) -> 0
L12: =IF(WELLNAME="","",(FLUIDTOTAL*(1-(WC/100)))) | O12: =IF(WELLNAME="","",IF(GAS=0,0,(GAS*1000000)/OIL)) | AR12: =IF(C12="",0,"KHALDA_WELLTEST1") -> 0 | AS12: =IF(AR12="","",REPORTDATE-1) -> 46298 | AT12: =UPPER(IF(AR12="","",$AQ$4&C12)) -> 9 | AU12: =UPPER(IF(AR12="","",$AQ$4&C12)) -> 9 | AV12: =IF(AR12="","",P12) -> 0 | AW12: =IF(AR12=0,0,Z12) -> 0 | AX12: =IF(AR12="","",J12) -> 0 | AY12: =IF(AR12="","",M12*1000) -> 0 | AZ12: =IF(AR12="","",F12) -> 0 | BA12: =IF(AR12="","",G12) -> 0 | BB12: =IF(AR12="","",H12) -> 0 | BC12: =IF(AR12="","",I12) -> 0 | BD12: =IF(AR12="","",Q12) -> 0 | BE12: =IF(AR12="","",R12) -> 0 | BF12: =IF(AR12="","",K12) -> 0 | BI12: =IF(AR12=0,"",200) | BJ12: =N12 -> 0 | BK12: =IF(AR12="","",W12) -> 0
L13: =IF(WELLNAME="","",(FLUIDTOTAL*(1-(WC/100)))) | O13: =IF(WELLNAME="","",IF(GAS=0,0,(GAS*1000000)/OIL)) | AR13: =IF(C13="",0,"KHALDA_WELLTEST1") -> 0 | AS13: =IF(AR13="","",REPORTDATE-1) -> 46298 | AT13: =UPPER(IF(AR13="","",$AQ$4&C13)) -> 9 | AU13: =UPPER(IF(AR13="","",$AQ$4&C13)) -> 9 | AV13: =IF(AR13="","",P13) -> 0 | AW13: =IF(AR13=0,0,Z13) -> 0 | AX13: =IF(AR13="","",J13) -> 0 | AY13: =IF(AR13="","",M13*1000) -> 0 | AZ13: =IF(AR13="","",F13) -> 0 | BA13: =IF(AR13="","",G13) -> 0 | BB13: =IF(AR13="","",H13) -> 0 | BC13: =IF(AR13="","",I13) -> 0 | BD13: =IF(AR13="","",Q13) -> 0 | BE13: =IF(AR13="","",R13) -> 0 | BF13: =IF(AR13="","",K13) -> 0 | BI13: =IF(AR13=0,"",200) | BJ13: =N13 -> 0 | BK13: =IF(AR13="","",W13) -> 0
L14: =IF(WELLNAME="","",(FLUIDTOTAL*(1-(WC/100)))) | O14: =IF(WELLNAME="","",IF(GAS=0,0,(GAS*1000000)/OIL)) | AR14: =IF(C14="",0,"KHALDA_WELLTEST1") -> 0 | AS14: =IF(AR14="","",REPORTDATE-1) -> 46298 | AT14: =UPPER(IF(AR14="","",$AQ$4&C14)) -> 9 | AU14: =UPPER(IF(AR14="","",$AQ$4&C14)) -> 9 | AV14: =IF(AR14="","",P14) -> 0 | AW14: =IF(AR14=0,0,Z14) -> 0 | AX14: =IF(AR14="","",J14) -> 0 | AY14: =IF(AR14="","",M14*1000) -> 0 | AZ14: =IF(AR14="","",F14) -> 0 | BA14: =IF(AR14="","",G14) -> 0 | BB14: =IF(AR14="","",H14) -> 0 | BC14: =IF(AR14="","",I14) -> 0 | BD14: =IF(AR14="","",Q14) -> 0 | BE14: =IF(AR14="","",R14) -> 0 | BF14: =IF(AR14="","",K14) -> 0 | BI14: =IF(AR14=0,"",200) | BJ14: =N14 -> 0 | BK14: =IF(AR14="","",W14) -> 0

Sheet WELL DATA
B1: WELL DATA - OIL WELLS | E1: =SUMIF(WSTATUS,"=SI",HOURS) -> 0 | I1: TEMPLATE MOD NEEDED | O1: =REPDATE -> 46299 | AD1: ='DATA INPUT'!E26/((SUMIF(FIELD,"WD33",EST_PROD))+(SUMIF(FIELD,"WD33 V",EST_PROD))) -> 0.22365527 | AE1: ='DATA INPUT'!E22/(SUMIF(FIELD,"WD33-15",EST_PROD)+SUMIF(FIELD,"WD33-C",EST_PROD)+SUMIF(FIELD,"WD-33K",EST_PROD)+SUMIF(FIELD,"WD33 H",EST_PROD)+SUMIF(FIELD,"WD33 j",EST_PROD)) -> 1.2142444 | AF1: =REPORT!L43/(SUM('WELL DATA'!AF5:AF165)+SUM(H5:H164)) -> 0.99496578 | AG1: =(REPORT!H39-REPORT!L9-'DATA INPUT'!E21-'DATA INPUT'!E24-AG86-'DATA INPUT'!E32)/(SUM(AG5:AG165)-AG86-AG87) -> 0.99777234 | AI1: Test is > 30 days old | DN1: NEED THESE PARAMETRES ADDING TO TEMPLATE
B2: WELL NAME | C2: ZONE | D2: STATUS | E2: =IF(E1>0,"CHECK HRS","HRS ONLINE") -> HRS ONLINE | F2: DEFER'd PROD STB | G2: DOWNTIME CAUSE Input will be blue if cause required | H2: LIFT GAS MMSCF/D | I2: CHOKE 64" | J2: WHFP PSI | K2: F/LINE PSI | L2: CASING PSI | M2: CASING STATUS | N2: FTHT °F | O2: LAST FLUID LEVELS | R2: PUMP DEPTH | S2: DAILY SAM DATA | V2: SUCKER ROD PUMP DATA | AA2: ESP TYPE | AE2: Hz | AF2: EST GAS PRODN | AG2: EST OIL PRODN | AH2: LAST WELL TEST | AN2: COMMENTS | CU2: FV TAG | CV2: DATE | CW2: WELL NAME | CX2: CHOKE 64" | CY2: WHFP PSI | CZ2: HRS ONLINE | DA2: STATUS | DC2: LIFT GAS MSCF/D | DD2: FTHT | DE2: DHP | DF2: SPM | DG2: SL | DH2: RPM | DI2: AMP 1 | DJ2: AMP 2 | DK2: AMP 3 | DL2: HZ | DM2: DAILY BS&W | DN2: DOWNTIME CAUSE | DO2: EST PROD | DP2: FIELD | EB2: FV TAG | EC2: DATE | ED2: WELL NAME | EE2: CHOKE 64" | EF2: WHFP PSI | EG2: HRS ONLINE | EH2: STATUS | EI2: CSG PSI | EJ2: CSG STAT | EK2: DOWNTIME CAUSE | EL2: DAILY BS&W | EM2: PUMP SIZE | EN2: DEFER PROD | EO2: FLINE PSI | EP2: PUMP UNIT SIZE | EQ2: SPM"Strock Per Minute" | ER2: DATE OF DOWNLOAD | ES2: SL"Strock Length" | ET2: AMP1 | EU2: AMP2 | EV2: AMP3 | EW2: RPM | EX2: HZ | EY2: PUMP TYPE | EZ2: RUNTIME % | FA2: INF PROD | FB2: PUMP FILLAGE% | FC2: PUMP FILL SET PT% | FD2: COMMENTS | FE2: FIELD
O3: DATE | P3: DFL | Q3: NLAP | S3: RUNTIME % | T3: INF PROD | U3: PUMP FILLAGE% | V3: PUMP INIT SIZE | W3: PUMP SIZE | X3: SL | Y3: SPM | Z3: DATE OF DONWLOAD | AD3: AMPS | AH3: DATE | AI3: BFPD | AJ3: BS&W % | AK3: MMSCFD | AL3: Salinity, PPM | AM3: BOPD | CT3: 9
E4: 0 | F4: =IF(OR(WSTATUS="T&A",DTCAUSE="PUMP OFF MODE",DTCAUSE="UNDER LOAD", DTCAUSE="NO RECOVERY - CEASE TO FLOW"),0,BOPD/24*(24-HOURS)) -> 0 | AF4: =AK4/24*D4 -> 0 | AG4: =AM4/24*E4 -> 0 | AM4: =IF(BFPD=0,0,BFPD*(1-BSW/100)) -> 0 | CU4: KHALDA_WELL1 | CV4: =REPORTDATE-1 -> 46298 | CW4: =$CT$3&B4 -> 9 | CX4: =I4 -> 0 | CY4: =J4 -> 0 | CZ4: =E4 -> 0 | DA4: =IF(CZ4=0,"SI",D4) -> SI | DC4: =H4*1000 -> 0 | DD4: =N4 -> 0 | DE4: =V4 -> 0 | DF4: =W4 -> 0 | DG4: =X4 -> 0 | DH4: =Z4 -> 0 | DI4: =AD4 -> 0 | DL4: =AE4 -> 0 | DM4: =AG4 -> 0 | DN4: =IF(G4="","",G4) | DO4: =AM4/24*HOURS -> 0 | DP4: =IF(OR(D4="SI",B4="",D4="T&A"),"",VLOOKUP(B4,WELL_FIELD,2))
B5: AG-02A | C5: ARD | D5: G/L | E5: 24 | F5: =IF(E5=0,0,((AI5*(1-(AJ5/100)))/24)*(24-HOURS)) -> 0 | H5: 1.43 | I5: NO P.CK | J5: 230 | K5: 230 | L5: 616 | AF5: =AK5/24*E5 -> 0.033 | AG5: =AM5/24*E5 -> 440.55 | AH5: 46296 | AI5: 445 | AJ5: 1 | AK5: 0.033 | AM5: =IF(BFPD=0,0,BFPD*(1-BSW/100)) -> 440.55 | CJ5: =+IF(D5="SI",0,AI5*AJ5/100) -> 4.45 | CU5: KHALDA_WELL1 | CV5: =REPORTDATE-1 -> 46298 | CW5: =$CT$3&B5 -> 9AG-02A | CX5: =I5 -> NO P.CK | CY5: =J5 -> 230 | CZ5: =E5 -> 24 | DA5: =IF(CZ5=0,"SI",D5) -> G/L | DC5: =E5*((H5*1000)/24) -> 1430 | DD5: =N5 -> 0 | DE5: =V5 -> 0 | DF5: =W5 -> 0 | DG5: =X5 -> 0 | DH5: =Z5 -> 0 | DI5: =AD5 -> 0 | DL5: =AE5 -> 0 | DM5: =AG5 -> 440.55 | DN5: =IF(G5="","",G5) | DO5: =AM5/24*HOURS -> 440.55 | DP5: =IF(OR(D5="SI",B5="",D5="T&A"),"",VLOOKUP(B5,WELL_FIELD,2)) -> SAG | EB5: =IF(B5="","","KHALDA_WELL") -> KHALDA_WELL | EC5: =REPORTDATE-1 -> 46298 | ED5: =B5 -> AG-02A | EE5: =I5 -> NO P.CK | EF5: =J5 -> 230 | EG5: =E5 -> 24 | EH5: =IF(CZ5=0,"SI",D5) -> G/L | EK5: =IF(G5="","",G5) | EL5: =AJ5 -> 1 | EM5: =W5 -> 0 | EQ5: =Y5 -> 0 | ER5: =Z5 -> 0 | ES5: =X5 -> 0 | ET5: =AD5 -> 0 | EX5: =AE5 -> 0 | EZ5: =S5 -> 0 | FA5: =T5 -> 0 | FB5: =U5 -> 0 | FD5: =AN5 -> 0
B6: AG-03 | C6: MULTIZONE | D6: NF | E6: 24 | F6: =IF(E6=0,0,((AI6*(1-(AJ6/100)))/24)*(24-HOURS)) -> 0 | I6: NO P.CK | J6: 145 | K6: 145 | L6: 0 | AF6: =AK6/24*E6 -> 0.365 | AG6: =AM6/24*E6 -> 0 | AH6: 45805 | AI6: 0 | AJ6: 0 | AK6: 0.365 | AM6: =IF(BFPD=0,0,BFPD*(1-BSW/100)) -> 0 | CJ6: =+IF(D6="SI",0,AI6*AJ6/100) -> 0 | CU6: KHALDA_WELL2 | CV6: =REPORTDATE-1 -> 46298 | CW6: =$CT$3&B6 -> 9AG-03 | CX6: =I6 -> NO P.CK | CY6: =J6 -> 145 | CZ6: =E6 -> 24 | DA6: =IF(CZ6=0,"SI",D6) -> NF | DC6: =E6*((H6*1000)/24) -> 0 | DD6: =N6 -> 0 | DE6: =V6 -> 0 | DF6: =W6 -> 0 | DG6: =X6 -> 0 | DH6: =Z6 -> 0 | DI6: =AD6 -> 0 | DL6: =AE6 -> 0 | DM6: =AG6 -> 0 | DN6: =IF(G6="","",G6) | DO6: =AM6/24*HOURS -> 0 | DP6: =IF(OR(D6="SI",B6="",D6="T&A"),"",VLOOKUP(B6,WELL_FIELD,2)) -> AG | EB6: =IF(B6="","","KHALDA_WELL") -> KHALDA_WELL | EC6: =REPORTDATE-1 -> 46298 | ED6: =B6 -> AG-03 | EE6: =I6 -> NO P.CK | EF6: =J6 -> 145 | EG6: =E6 -> 24 | EH6: =IF(CZ6=0,"SI",D6) -> NF | EK6: =IF(G6="","",G6) | EL6: =AJ6 -> 0 | EM6: =W6 -> 0 | EQ6: =Y6 -> 0 | ER6: =Z6 -> 0 | ES6: =X6 -> 0 | ET6: =AD6 -> 0 | EX6: =AE6 -> 0 | EZ6: =S6 -> 0 | FA6: =T6 -> 0 | FB6: =U6 -> 0 | FD6: =AN6 -> 0
B7: AG-10 | C7: BAH | D7: G/L | E7: 24 | F7: =IF(E7=0,0,((AI7*(1-(AJ7/100)))/24)*(24-HOURS)) -> 0 | H7: 1.09 | I7: NO P.CK | J7: 110 | K7: 110 | L7: 807 | AF7: =AK7/24*E7 -> 0.052 | AG7: =AM7/24*E7 -> 20.79 | AH7: 46249 | AI7: 21 | AJ7: 1 | AK7: 0.052 | AM7: =IF(BFPD=0,0,BFPD*(1-BSW/100)) -> 20.79 | CJ7: =+IF(D7="SI",0,AI7*AJ7/100) -> 0.21 | CU7: KHALDA_WELL3 | CV7: =REPORTDATE-1 -> 46298 | CW7: =$CT$3&B7 -> 9AG-10 | CX7: =I7 -> NO P.CK | CY7: =J7 -> 110 | CZ7: =E7 -> 24 | DA7: =IF(CZ7=0,"SI",D7) -> G/L | DC7: =E7*((H7*1000)/24) -> 1090 | DD7: =N7 -> 0 | DE7: =V7 -> 0 | DF7: =W7 -> 0 | DG7: =X7 -> 0 | DH7: =Z7 -> 0 | DI7: =AD7 -> 0 | DL7: =AE7 -> 0 | DM7: =AG7 -> 20.79 | DN7: =IF(G7="","",G7) | DO7: =AM7/24*HOURS -> 20.79 | DP7: =IF(OR(D7="SI",B7="",D7="T&A"),"",VLOOKUP(B7,WELL_FIELD,2)) -> AG | EB7: =IF(B7="","","KHALDA_WELL") -> KHALDA_WELL | EC7: =REPORTDATE-1 -> 46298 | ED7: =B7 -> AG-10 | EE7: =I7 -> NO P.CK | EF7: =J7 -> 110 | EG7: =E7 -> 24 | EH7: =IF(CZ7=0,"SI",D7) -> G/L | EK7: =IF(G7="","",G7) | EL7: =AJ7 -> 1 | EM7: =W7 -> 0 | EQ7: =Y7 -> 0 | ER7: =Z7 -> 0 | ES7: =X7 -> 0 | ET7: =AD7 -> 0 | EX7: =AE7 -> 0 | EZ7: =S7 -> 0 | FA7: =T7 -> 0 | FB7: =U7 -> 0 | FD7: =AN7 -> 0
B8: AG-12 | C8: BAH | D8: SI | E8: 0 | F8: =IF(E8=0,0,((AI8*(1-(AJ8/100)))/24)*(24-HOURS)) -> 0 | I8: NO P.CK | J8: 0 | K8: 0 | L8: 0 | AF8: =AK8/24*E8 -> 0 | AG8: =AM8/24*E8 -> 0 | AH8: 44049 | AI8: 0 | AK8: 0.185 | AM8: =IF(BFPD=0,0,BFPD*(1-BSW/100)) -> 0 | CJ8: =+IF(D8="SI",0,AI8*AJ8/100) -> 0 | CU8: KHALDA_WELL4 | CV8: =REPORTDATE-1 -> 46298 | CW8: =$CT$3&B8 -> 9AG-12 | CX8: =I8 -> NO P.CK | CY8: =J8 -> 0 | CZ8: =E8 -> 0 | DA8: =IF(CZ8=0,"SI",D8) -> SI | DC8: =E8*((H8*1000)/24) -> 0 | DD8: =N8 -> 0 | DE8: =V8 -> 0 | DF8: =W8 -> 0 | DG8: =X8 -> 0 | DH8: =Z8 -> 0 | DI8: =AD8 -> 0 | DL8: =AE8 -> 0 | DM8: =AG8 -> 0 | DN8: =IF(G8="","",G8) | DO8: =AM8/24*HOURS -> 0 | DP8: =IF(OR(D8="SI",B8="",D8="T&A"),"",VLOOKUP(B8,WELL_FIELD,2)) | EB8: =IF(B8="","","KHALDA_WELL") -> KHALDA_WELL | EC8: =REPORTDATE-1 -> 46298 | ED8: =B8 -> AG-12 | EE8: =I8 -> NO P.CK | EF8: =J8 -> 0 | EG8: =E8 -> 0 | EH8: =IF(CZ8=0,"SI",D8) -> SI | EK8: =IF(G8="","",G8) | EL8: =AJ8 -> 0 | EM8: =W8 -> 0 | EQ8: =Y8 -> 0 | ER8: =Z8 -> 0 | ES8: =X8 -> 0 | ET8: =AD8 -> 0 | EX8: =AE8 -> 0 | EZ8: =S8 -> 0 | FA8: =T8 -> 0 | FB8: =U8 -> 0 | FD8: =AN8 -> 0
B9: AG-13 | C9: ARE | D9: G/L | E9: 24 | F9: =IF(E9=0,0,((AI9*(1-(AJ9/100)))/24)*(24-HOURS)) -> 0 | H9: 0.95949584 | I9: NO P.CK | J9: 140 | K9: 140 | L9: 340 | AF9: =AK9/24*E9 -> 0.071 | AG9: =AM9/24*E9 -> 52.47 | AH9: 46253 | AI9: 53 | AJ9: 1 | AK9: 0.071 | AM9: =IF(BFPD=0,0,BFPD*(1-BSW/100)) -> 52.47 | CJ9: =+IF(D9="SI",0,AI9*AJ9/100) -> 0.53 | CU9: KHALDA_WELL5 | CV9: =REPORTDATE-1 -> 46298 | CW9: =$CT$3&B9 -> 9AG-13 | CX9: =I9 -> NO P.CK | CY9: =J9 -> 140 | CZ9: =E9 -> 24 | DA9: =IF(CZ9=0,"SI",D9) -> G/L | DC9: =E9*((H9*1000)/24) -> 959.49584 | DD9: =N9 -> 0 | DE9: =V9 -> 0 | DF9: =W9 -> 0 | DG9: =X9 -> 0 | DH9: =Z9 -> 0 | DI9: =AD9 -> 0 | DL9: =AE9 -> 0 | DM9: =AG9 -> 52.47 | DN9: =IF(G9="","",G9) | DO9: =AM9/24*HOURS -> 52.47 | DP9: =IF(OR(D9="SI",B9="",D9="T&A"),"",VLOOKUP(B9,WELL_FIELD,2)) -> AG | EB9: =IF(B9="","","KHALDA_WELL") -> KHALDA_WELL | EC9: =REPORTDATE-1 -> 46298 | ED9: =B9 -> AG-13 | EE9: =I9 -> NO P.CK | EF9: =J9 -> 140 | EG9: =E9 -> 24 | EH9: =IF(CZ9=0,"SI",D9) -> G/L | EK9: =IF(G9="","",G9) | EL9: =AJ9 -> 1 | EM9: =W9 -> 0 | EQ9: =Y9 -> 0 | ER9: =Z9 -> 0 | ES9: =X9 -> 0 | ET9: =AD9 -> 0 | EX9: =AE9 -> 0 | EZ9: =S9 -> 0 | FA9: =T9 -> 0 | FB9: =U9 -> 0 | FD9: =AN9 -> 0
B10: AG-14 | C10: ARE | D10: SI | E10: 0 | F10: =IF(E10=0,0,((AI10*(1-(AJ10/100)))/24)*(24-HOURS)) -> 0 | H10: 0 | I10: NO P.CK | J10: 0 | K10: 0 | L10: 0 | AF10: =AK10/24*E10 -> 0 | AG10: =AM10/24*E10 -> 0 | AH10: 42339 | AI10: 2.7 | AJ10: 15 | AK10: 0.009 | AM10: =IF(BFPD=0,0,BFPD*(1-BSW/100)) -> 2.295 | AN10: Circulation gas | CJ10: =+IF(D10="SI",0,AI10*AJ10/100) -> 0 | CU10: KHALDA_WELL6 | CV10: =REPORTDATE-1 -> 46298 | CW10: =$CT$3&B10 -> 9AG-14 | CX10: =I10 -> NO P.CK | CY10: =J10 -> 0 | CZ10: =E10 -> 0 | DA10: =IF(CZ10=0,"SI",D10) -> SI | DC10: =E10*((H10*1000)/24) -> 0 | DD10: =N10 -> 0 | DE10: =V10 -> 0 | DF10: =W10 -> 0 | DG10: =X10 -> 0 | DH10: =Z10 -> 0 | DI10: =AD10 -> 0 | DL10: =AE10 -> 0 | DM10: =AG10 -> 0 | DN10: =IF(G10="","",G10) | DO10: =AM10/24*HOURS -> 0 | DP10: =IF(OR(D10="SI",B10="",D10="T&A"),"",VLOOKUP(B10,WELL_FIELD,2)) | EB10: =IF(B10="","","KHALDA_WELL") -> KHALDA_WELL | EC10: =REPORTDATE-1 -> 46298 | ED10: =B10 -> AG-14 | EE10: =I10 -> NO P.CK | EF10: =J10 -> 0 | EG10: =E10 -> 0 | EH10: =IF(CZ10=0,"SI",D10) -> SI | EK10: =IF(G10="","",G10) | EL10: =AJ10 -> 15 | EM10: =W10 -> 0 | EQ10: =Y10 -> 0 | ER10: =Z10 -> 0 | ES10: =X10 -> 0 | ET10: =AD10 -> 0 | EX10: =AE10 -> 0 | EZ10: =S10 -> 0 | FA10: =T10 -> 0 | FB10: =U10 -> 0 | FD10: =AN10 -> Circulation gas
B11: AG-15 | C11: ARG/ARE | D11: SI | E11: 0 | F11: =IF(E11=0,0,((AI11*(1-(AJ11/100)))/24)*(24-HOURS)) -> 0 | H11: 0 | I11: NO P.CK | J11: 0 | K11: 0 | L11: 0 | AF11: =AK11/24*E11 -> 0 | AG11: =AM11/24*E11 -> 0 | AH11: 46209 | AI11: 0 | AK11: 0.286 | AM11: =IF(BFPD=0,0,BFPD*(1-BSW/100)) -> 0 | CJ11: =+IF(D11="SI",0,AI11*AJ11/100) -> 0 | CU11: KHALDA_WELL7 | CV11: =REPORTDATE-1 -> 46298 | CW11: =$CT$3&B11 -> 9AG-15 | CX11: =I11 -> NO P.CK | CY11: =J11 -> 0 | CZ11: =E11 -> 0 | DA11: =IF(CZ11=0,"SI",D11) -> SI | DC11: =E11*((H11*1000)/24) -> 0 | DD11: =N11 -> 0 | DE11: =V11 -> 0 | DF11: =W11 -> 0 | DG11: =X11 -> 0 | DH11: =Z11 -> 0 | DI11: =AD11 -> 0 | DL11: =AE11 -> 0 | DM11: =AG11 -> 0 | DN11: =IF(G11="","",G11) | DO11: =AM11/24*HOURS -> 0 | DP11: =IF(OR(D11="SI",B11="",D11="T&A"),"",VLOOKUP(B11,WELL_FIELD,2)) | EB11: =IF(B11="","","KHALDA_WELL") -> KHALDA_WELL | EC11: =REPORTDATE-1 -> 46298 | ED11: =B11 -> AG-15 | EE11: =I11 -> NO P.CK | EF11: =J11 -> 0 | EG11: =E11 -> 0 | EH11: =IF(CZ11=0,"SI",D11) -> SI | EK11: =IF(G11="","",G11) | EL11: =AJ11 -> 0 | EM11: =W11 -> 0 | EQ11: =Y11 -> 0 | ER11: =Z11 -> 0 | ES11: =X11 -> 0 | ET11: =AD11 -> 0 | EX11: =AE11 -> 0 | EZ11: =S11 -> 0 | FA11: =T11 -> 0 | FB11: =U11 -> 0 | FD11: =AN11 -> 0
B12: AG-16A | C12: MULTIZONE | D12: SI | E12: 0 | F12: =IF(E12=0,0,((AI12*(1-(AJ12/100)))/24)*(24-HOURS)) -> 0 | I12: OPEN | J12: 0 | K12: 0 | L12: 0 | AF12: =AK12/24*E12 -> 0 | AG12: =AM12/24*E12 -> 0 | AH12: 44871 | AI12: 64 | AJ12: 38 | AK12: 0 | AM12: =IF(BFPD=0,0,BFPD*(1-BSW/100)) -> 39.68 | CJ12: =+IF(D12="SI",0,AI12*AJ12/100) -> 0 | CU12: KHALDA_WELL8 | CV12: =REPORTDATE-1 -> 46298 | CW12: =$CT$3&B12 -> 9AG-16A | CX12: =I12 -> OPEN | CY12: =J12 -> 0 | CZ12: =E12 -> 0 | DA12: =IF(CZ12=0,"SI",D12) -> SI | DC12: =E12*((H12*1000)/24) -> 0 | DD12: =N12 -> 0 | DE12: =V12 -> 0 | DF12: =W12 -> 0 | DG12: =X12 -> 0 | DH12: =Z12 -> 0 | DI12: =AD12 -> 0 | DL12: =AE12 -> 0 | DM12: =AG12 -> 0 | DN12: =IF(G12="","",G12) | DO12: =AM12/24*HOURS -> 0 | DP12: =IF(OR(D12="SI",B12="",D12="T&A"),"",VLOOKUP(B12,WELL_FIELD,2)) | EB12: =IF(B12="","","KHALDA_WELL") -> KHALDA_WELL | EC12: =REPORTDATE-1 -> 46298 | ED12: =B12 -> AG-16A | EE12: =I12 -> OPEN | EF12: =J12 -> 0 | EG12: =E12 -> 0 | EH12: =IF(CZ12=0,"SI",D12) -> SI | EK12: =IF(G12="","",G12) | EL12: =AJ12 -> 38 | EM12: =W12 -> 0 | EQ12: =Y12 -> 0 | ER12: =Z12 -> 0 | ES12: =X12 -> 0 | ET12: =AD12 -> 0 | EX12: =AE12 -> 0 | EZ12: =S12 -> 0 | FA12: =T12 -> 0 | FB12: =U12 -> 0 | FD12: =AN12 -> 0
B13: AG-21 | C13: MULTIZONE | D13: G/L | E13: 21 | F13: =IF(E13=0,0,((AI13*(1-(AJ13/100)))/24)*(24-HOURS)) -> 5.6925 | G13: Wireline Intervention - Gauging | H13: 0.75 | I13: NO P.CK | J13: 70 | K13: 70 | L13: 504 | AF13: =AK13/24*E13 -> 0.032375 | AG13: =AM13/24*E13 -> 39.8475 | AH13: 46170 | AI13: 46 | AJ13: 1 | AK13: 0.037 | AM13: =IF(BFPD=0,0,BFPD*(1-BSW/100)) -> 45.54 | CJ13: =+IF(D13="SI",0,AI13*AJ13/100) -> 0.46 | CU13: KHALDA_WELL9 | CV13: =REPORTDATE-1 -> 46298 | CW13: =$CT$3&B13 -> 9AG-21 | CX13: =I13 -> NO P.CK | CY13: =J13 -> 70 | CZ13: =E13 -> 21 | DA13: =IF(CZ13=0,"SI",D13) -> G/L | DC13: =E13*((H13*1000)/24) -> 656.25 | DD13: =N13 -> 0 | DE13: =V13 -> 0 | DF13: =W13 -> 0 | DG13: =X13 -> 0 | DH13: =Z13 -> 0 | DI13: =AD13 -> 0 | DL13: =AE13 -> 0 | DM13: =AG13 -> 39.8475 | DN13: =IF(G83="","",G83) | DO13: =AM13/24*HOURS -> 39.8475 | DP13: =IF(OR(D13="SI",B13="",D13="T&A"),"",VLOOKUP(B13,WELL_FIELD,2)) -> AG | EB13: =IF(B13="","","KHALDA_WELL") -> KHALDA_WELL | EC13: =REPORTDATE-1 -> 46298 | ED13: =B13 -> AG-21 | EE13: =I13 -> NO P.CK | EF13: =J13 -> 70 | EG13: =E13 -> 21 | EH13: =IF(CZ13=0,"SI",D13) -> G/L | EK13: =IF(G13="","",G13) -> Wireline Intervention - Gauging | EL13: =AJ13 -> 1 | EM13: =W13 -> 0 | EQ13: =Y13 -> 0 | ER13: =Z13 -> 0 | ES13: =X13 -> 0 | ET13: =AD13 -> 0 | EX13: =AE13 -> 0 | EZ13: =S13 -> 0 | FA13: =T13 -> 0 | FB13: =U13 -> 0 | FD13: =AN13 -> 0
B14: AG-22 | C14: MULTIZONE | D14: SI | E14: 0 | F14: =IF(E14=0,0,((AI14*(1-(AJ14/100)))/24)*(24-HOURS)) -> 0 | I14: 38 | J14: 710 | K14: 170 | L14: 0 | AF14: =AK14/24*E14 -> 0 | AG14: =AM14/24*E14 -> 0 | AH14: 44720 | AI14: 224 | AJ14: 99 | AK14: 1.824 | AM14: =IF(BFPD=0,0,BFPD*(1-BSW/100)) -> 2.24 | CJ14: =+IF(D14="SI",0,AI14*AJ14/100) -> 0 | CU14: KHALDA_WELL9 | CV14: =REPORTDATE-1 -> 46298 | CW14: =$CT$3&B14 -> 9AG-22 | CX14: =I14 -> 38 | CY14: =J14 -> 710 | CZ14: =E14 -> 0 | DA14: =IF(CZ14=0,"SI",D14) -> SI | DC14: =E14*((H14*1000)/24) -> 0 | DD14: =N14 -> 0 | DE14: =V14 -> 0 | DF14: =W14 -> 0 | DG14: =X14 -> 0 | DH14: =Z14 -> 0 | DI14: =AD14 -> 0 | DL14: =AE14 -> 0 | DM14: =AG14 -> 0 | DN14: =IF(G86="","",G86) | DO14: =AM14/24*HOURS -> 0 | DP14: =IF(OR(D14="SI",B14="",D14="T&A"),"",VLOOKUP(B14,WELL_FIELD,2)) | EB14: =IF(B14="","","KHALDA_WELL") -> KHALDA_WELL | EC14: =REPORTDATE-1 -> 46298 | ED14: =B14 -> AG-22 | EE14: =I14 -> 38 | EF14: =J14 -> 710 | EG14: =E14 -> 0 | EH14: =IF(CZ14=0,"SI",D14) -> SI | EK14: =IF(G14="","",G14) | EL14: =AJ14 -> 99 | EM14: =W14 -> 0 | EQ14: =Y14 -> 0 | ER14: =Z14 -> 0 | ES14: =X14 -> 0 | ET14: =AD14 -> 0 | EX14: =AE14 -> 0 | EZ14: =S14 -> 0 | FA14: =T14 -> 0 | FB14: =U14 -> 0 | FD14: =AN14 -> 0
B15: AG-24 | C15: ARD | D15: NF | E15: 12 | F15: =IF(E15=0,0,((AI15*(1-(AJ15/100)))/24)*(24-HOURS)) -> 0 | G15: Low Reservoir Pressure/Depleted | I15: NO P.CK | J15: 130 | K15: 130 | L15: 0 | AF15: =AK15/24*E15 -> 0.06 | AG15: =AM15/24*E15 -> 0 | AH15: 43779 | AI15: 0 | AJ15: 0 | AK15: 0.12 | AM15: =IF(BFPD=0,0,BFPD*(1-BSW/100)) -> 0 | CJ15: =+IF(D15="SI",0,AI15*AJ15/100) -> 0 | CU15: KHALDA_WELL10 | CV15: =REPORTDATE-1 -> 46298 | CW15: =$CT$3&B15 -> 9AG-24 | CX15: =I15 -> NO P.CK | CY15: =J15 -> 130 | CZ15: =E15 -> 12 | DA15: =IF(CZ15=0,"SI",D15) -> NF | DC15: =E15*((H15*1000)/24) -> 0 | DD15: =N15 -> 0 | DE15: =V15 -> 0 | DF15: =W15 -> 0 | DG15: =X15 -> 0 | DH15: =Z15 -> 0 | DI15: =AD15 -> 0 | DL15: =AE15 -> 0 | DM15: =AG15 -> 0 | DN15: =IF(G87="","",G87) | DO15: =AM15/24*HOURS -> 0 | DP15: =IF(OR(D15="SI",B15="",D15="T&A"),"",VLOOKUP(B15,WELL_FIELD,2)) -> AG | EB15: =IF(B15="","","KHALDA_WELL") -> KHALDA_WELL | EC15: =REPORTDATE-1 -> 46298 | ED15: =B15 -> AG-24 | EE15: =I15 -> NO P.CK | EF15: =J15 -> 130 | EG15: =E15 -> 12 | EH15: =IF(CZ15=0,"SI",D15) -> NF | EK15: =IF(G15="","",G15) -> Low Reservoir Pressure/Depleted | EL15: =AJ15 -> 0 | EM15: =W15 -> 0 | EQ15: =Y15 -> 0 | ER15: =Z15 -> 0 | ES15: =X15 -> 0 | ET15: =AD15 -> 0 | EX15: =AE15 -> 0 | EZ15: =S15 -> 0 | FA15: =T15 -> 0 | FB15: =U15 -> 0 | FD15: =AN15 -> 0
B16: AG-25ST1 | C16: MULTIZONE | D16: SI | E16: 0 | F16: =IF(E16=0,0,((AI16*(1-(AJ16/100)))/24)*(24-HOURS)) -> 0 | H16: 0 | I16: NO P.CK | J16: 0 | K16: 0 | L16: 0 | AC16: 50 | AF16: =AK16/24*E16 -> 0 | AG16: =AM16/24*E16 -> 0 | AH16: 43314 | AI16: 21 | AJ16: 0.4 | AK16: 0 | AM16: =IF(BFPD=0,0,BFPD*(1-BSW/100)) -> 20.916 | AN16: The well is SI due to low production & gas lift optimization | CJ16: =+IF(D16="SI",0,AI16*AJ16/100) -> 0 | CU16: KHALDA_WELL11 | CV16: =REPORTDATE-1 -> 46298 | CW16: =$CT$3&B16 -> 9AG-25ST1 | CX16: =I16 -> NO P.CK | CY16: =J16 -> 0 | CZ16: =E16 -> 0 | DA16: =IF(CZ16=0,"SI",D16) -> SI | DC16: =E16*((H16*1000)/24) -> 0 | DD16: =N16 -> 0 | DE16: =V16 -> 0 | DF16: =W16 -> 0 | DG16: =X16 -> 0 | DH16: =Z16 -> 0 | DI16: =AD16 -> 0 | DL16: =AE16 -> 0 | DM16: =AG16 -> 0 | DN16: =IF(G88="","",G88) | DO16: =AM16/24*HOURS -> 0 | DP16: =IF(OR(D16="SI",B16="",D16="T&A"),"",VLOOKUP(B16,WELL_FIELD,2)) | EB16: =IF(B16="","","KHALDA_WELL") -> KHALDA_WELL | EC16: =REPORTDATE-1 -> 46298 | ED16: =B16 -> AG-25ST1 | EE16: =I16 -> NO P.CK | EF16: =J16 -> 0 | EG16: =E16 -> 0 | EH16: =IF(CZ16=0,"SI",D16) -> SI | EK16: =IF(G16="","",G16) | EL16: =AJ16 -> 0.4 | EM16: =W16 -> 0 | EQ16: =Y16 -> 0 | ER16: =Z16 -> 0 | ES16: =X16 -> 0 | ET16: =AD16 -> 0 | EX16: =AE16 -> 0 | EZ16: =S16 -> 0 | FA16: =T16 -> 0 | FB16: =U16 -> 0 | FD16: =AN16 -> The well is SI due to low production & gas lift optimization
B17: AG-27ST2 | C17: BAH | D17: SI | E17: 0 | F17: =IF(E17=0,0,((AI17*(1-(AJ17/100)))/24)*(24-HOURS)) -> 0 | I17: NO P.CK | J17: 0 | K17: 0 | L17: 0 | AF17: =AK17/24*E17 -> 0 | AG17: =AM17/24*E17 -> 0 | AH17: 45364 | AI17: 32 | AJ17: 66 | AK17: 2.6 | AM17: =IF(BFPD=0,0,BFPD*(1-BSW/100)) -> 10.88 | CJ17: =+IF(D17="SI",0,AI17*AJ17/100) -> 0 | CU17: KHALDA_WELL12 | CV17: =REPORTDATE-1 -> 46298 | CW17: =$CT$3&B17 -> 9AG-27ST2 | CX17: =I17 -> NO P.CK | CY17: =J17 -> 0 | CZ17: =E17 -> 0 | DA17: =IF(CZ17=0,"SI",D17) -> SI | DC17: =E17*((H17*1000)/24) -> 0 | DD17: =N17 -> 0 | DE17: =V17 -> 0 | DF17: =W17 -> 0 | DG17: =X17 -> 0 | DH17: =Z17 -> 0 | DI17: =AD17 -> 0 | DL17: =AE17 -> 0 | DM17: =AG17 -> 0 | DN17: =IF(G17="","",G17) | DO17: =AM17/24*HOURS -> 0 | DP17: =IF(OR(D17="SI",B17="",D17="T&A"),"",VLOOKUP(B17,WELL_FIELD,2)) | EB17: =IF(B17="","","KHALDA_WELL") -> KHALDA_WELL | EC17: =REPORTDATE-1 -> 46298 | ED17: =B17 -> AG-27ST2 | EE17: =I17 -> NO P.CK | EF17: =J17 -> 0 | EG17: =E17 -> 0 | EH17: =IF(CZ17=0,"SI",D17) -> SI | EK17: =IF(G17="","",G17) | EL17: =AJ17 -> 66 | EM17: =W17 -> 0 | EQ17: =Y17 -> 0 | ER17: =Z17 -> 0 | ES17: =X17 -> 0 | ET17: =AD17 -> 0 | EX17: =AE17 -> 0 | EZ17: =S17 -> 0 | FA17: =T17 -> 0 | FB17: =U17 -> 0 | FD17: =AN17 -> 0
B18: AG-28 | C18: ARC | D18: SI | E18: 0 | F18: =IF(E18=0,0,((AI18*(1-(AJ18/100)))/24)*(24-HOURS)) -> 0 | H18: 0 | I18: NO P.CK | J18: 0 | K18: 0 | L18: 0 | AC18: 50 | AF18: =AK18/24*E18 -> 0 | AG18: =AM18/24*E18 -> 0 | AH18: 43310 | AI18: 113 | AJ18: 94 | AK18: 0 | AM18: =IF(BFPD=0,0,BFPD*(1-BSW/100)) -> 6.78 | AN18: The well is SI due to low production & gas lift optimization | CJ18: =+IF(D18="SI",0,AI18*AJ18/100) -> 0 | CU18: KHALDA_WELL13 | CV18: =REPORTDATE-1 -> 46298 | CW18: =$CT$3&B18 -> 9AG-28 | CX18: =I18 -> NO P.CK | CY18: =J18 -> 0 | CZ18: =E18 -> 0 | DA18: =IF(CZ18=0,"SI",D18) -> SI | DC18: =E18*((H18*1000)/24) -> 0 | DD18: =N18 -> 0 | DE18: =V18 -> 0 | DF18: =W18 -> 0 | DG18: =X18 -> 0 | DH18: =Z18 -> 0 | DI18: =AD18 -> 0 | DL18: =AE18 -> 0 | DM18: =AG18 -> 0 | DN18: =IF(G18="","",G18) | DO18: =AM18/24*HOURS -> 0 | DP18: =IF(OR(D18="SI",B18="",D18="T&A"),"",VLOOKUP(B18,WELL_FIELD,2)) | EB18: =IF(B18="","","KHALDA_WELL") -> KHALDA_WELL | EC18: =REPORTDATE-1 -> 46298 | ED18: =B18 -> AG-28 | EE18: =I18 -> NO P.CK | EF18: =J18 -> 0 | EG18: =E18 -> 0 | EH18: =IF(CZ18=0,"SI",D18) -> SI | EK18: =IF(G18="","",G18) | EL18: =AJ18 -> 94 | EM18: =W18 -> 0 | EQ18: =Y18 -> 0 | ER18: =Z18 -> 0 | ES18: =X18 -> 0 | ET18: =AD18 -> 0 | EX18: =AE18 -> 0 | EZ18: =S18 -> 0 | FA18: =T18 -> 0 | FB18: =U18 -> 0 | FD18: =AN18 -> The well is SI due to low production & gas lift optimization
B19: AG-29A | C19: ARC | D19: ESP | E19: 24 | F19: =IF(E19=0,0,((AI19*(1-(AJ19/100)))/24)*(24-HOURS)) -> 0 | I19: NO P.CK | J19: 110 | K19: 70 | L19: 0 | AA19: FLEX-10 | AD19: 30.6 | AE19: 52 | AF19: =AK19/24*E19 -> 0 | AG19: =AM19/24*E19 -> 108 | AH19: 46294 | AI19: 360 | AJ19: 70 | AK19: 0 | AL19: 51000 | AM19: =IF(BFPD=0,0,BFPD*(1-BSW/100)) -> 108 | CJ19: =+IF(D19="SI",0,AI19*AJ19/100) -> 252 | CU19: KHALDA_WELL14 | CV19: =REPORTDATE-1 -> 46298 | CW19: =$CT$3&B19 -> 9AG-29A | CX19: =I19 -> NO P.CK | CY19: =J19 -> 110 | CZ19: =E19 -> 24 | DA19: =IF(CZ19=0,"SI",D19) -> ESP | DC19: =E19*((H19*1000)/24) -> 0 | DD19: =N19 -> 0 | DE19: =V19 -> 0 | DF19: =W19 -> 0 | DG19: =X19 -> 0 | DH19: =Z19 -> 0 | DI19: =AD19 -> 30.6 | DL19: =AE19 -> 52 | DM19: =AG19 -> 108 | DN19: =IF(G19="","",G19) | DO19: =AM19/24*HOURS -> 108 | DP19: =IF(OR(D19="SI",B19="",D19="T&A"),"",VLOOKUP(B19,WELL_FIELD,2)) -> AG | EB19: =IF(B19="","","KHALDA_WELL") -> KHALDA_WELL | EC19: =REPORTDATE-1 -> 46298 | ED19: =B19 -> AG-29A | EE19: =I19 -> NO P.CK | EF19: =J19 -> 110 | EG19: =E19 -> 24 | EH19: =IF(CZ19=0,"SI",D19) -> ESP | EK19: =IF(G19="","",G19) | EL19: =AJ19 -> 70 | EM19: =W19 -> 0 | EQ19: =Y19 -> 0 | ER19: =Z19 -> 0 | ES19: =X19 -> 0 | ET19: =AD19 -> 30.6 | EX19: =AE19 -> 52 | EZ19: =S19 -> 0 | FA19: =T19 -> 0 | FB19: =U19 -> 0 | FD19: =AN19 -> 0
